Workbook

Sheet الواجهة الرئيسية
B2: نظام تقييم مهارات نافس الأكاديمي
B3: Academic Skills Assessment System – NAFIS
B4: عدد الطالبات: 99 | عدد المهارات: 10 | العام الدراسي: 1446 هـ
B5: ✨ يمكنك تعديل مسمى أي مهارة مباشرةً من هذه الكروت – وسيتم تحديثها تلقائياً في جميع صفحات الملف
B6: 📚 المهارة 1 | D6: 🔍 المهارة 2 | F6: 🧠 المهارة 3 | H6: 💡 المهارة 4 | J6: 🗣️ المهارة 5
B8: القراءة والفهم | D8: الاستيعاب والتحليل | F8: التفكير الناقد | H8: حل المشكلات | J8: التواصل اللغوي
B18: 📊 المهارة 6 | D18: 🎓 المهارة 7 | F18: ⚙️ المهارة 8 | H18: ✨ المهارة 9 | J18: 📐 المهارة 10
B20: الاستنتاج والتقييم | D20: الكفاءة المعرفية | F20: المنطق والتفكير | H20: الإبداع والابتكار | J20: التطبيق والتحليل
B32: جميع الحقوق محفوظة – نظام نافس الأكاديمي

Sheet قاعدة الأسماء
A2: قاعدة بيانات الطالبات المركزية – Master Sheet
A3: هذه الصفحة هي المرجع الرئيسي لأسماء الطالبات – تؿذّي جميع الصفحات تلقائياً
A4: م | B4: اسم الطالبة | C4: رقم الهوية | D4: الفصل | E4: اسم المعلمة | F4: تاريخ الإدخال
A5: 1 | B5: نورة أحمد السالم | C5: 1090000137 | D5: ثالث/1 | E5: أ. أمل العمري | F5: 1446/08/15 هـ
A6: 2 | B6: ريم محمد العتيبي | C6: 1090000274 | D6: ثالث/1 | E6: أ. أمل العمري | F6: 1446/08/15 هـ
A7: 3 | B7: سارة خالد الزهراني | C7: 1090000411 | D7: ثالث/1 | E7: أ. أمل العمري | F7: 1446/08/15 هـ
A8: 4 | B8: هند عبدالله المطيري | C8: 1090000548 | D8: ثالث/1 | E8: أ. أمل العمري | F8: 1446/08/15 هـ
A9: 5 | B9: ليلى سعد القحطاني | C9: 1090000685 | D9: ثالث/1 | E9: أ. أمل العمري | F9: 1446/08/15 هـ
A10: 6 | B10: مريم يوسف الشهري | C10: 1090000822 | D10: ثالث/1 | E10: أ. أمل العمري | F10: 1446/08/15 هـ
A11: 7 | B11: دانة فهد العنزي | C11: 1090000959 | D11: ثالث/1 | E11: أ. أمل العمري | F11: 1446/08/15 هـ
A12: 8 | B12: رنا عمر الدوسري | C12: 1090001096 | D12: ثالث/1 | E12: أ. أمل العمري | F12: 1446/08/15 هـ
A13: 9 | B13: أريج ناصر الحربي | C13: 1090001233 | D13: ثالث/1 | E13: أ. أمل العمري | F13: 1446/08/15 هـ
A14: 10 | B14: شيماء علي الغامدي | C14: 1090001370 | D14: ثالث/1 | E14: أ. أمل العمري | F14: 1446/08/15 هـ
A15: 11 | B15: أسماء إبراهيم البلوي | C15: 1090001507 | D15: ثالث/1 | E15: أ. أمل العمري | F15: 1446/08/15 هـ
A16: 12 | B16: غادة حسن الرشيدي | C16: 1090001644 | D16: ثالث/1 | E16: أ. أمل العمري | F16: 1446/08/15 هـ
... A103: 99 | B103: خلود فهيد الرويلي | C103: 1090013563 | D103: ثالث/3 | E103: أ. أمل العمري | F103: 1446/08/15 هـ

Sheet الاختبار القبلي
A2: الاختبار التشخيصي القبلي – Pre-Test
A3: إدخال درجات مهارات نافس العشر | التحليل الفوري تلقائي
A4: م | B4: اسم الطالبة | C4: ="م1 " & CHAR(10) & 'الواجهة الرئيسية'!B8 | D4: ="م2 " & CHAR(10) & 'الواجهة الرئيسية'!D8 | E4: ="م3 " & CHAR(10) & 'الواجهة الرئيسية'!F8 | F4: ="م4 " & CHAR(10) & 'الواجهة الرئيسية'!H8 | G4: ="م5 " & CHAR(10) & 'الواجهة الرئيسية'!J8 | H4: ="م6 " & CHAR(10) & 'الواجهة الرئيسية'!B20 | I4: ="م7 " & CHAR(10) & 'الواجهة الرئيسية'!D20 | J4: ="م8 " & CHAR(10) & 'الواجهة الرئيسية'!F20 | K4: ="م9 " & CHAR(10) & 'الواجهة الرئيسية'!H20 | L4: ="م10 " & CHAR(10) & 'الواجهة الرئيسية'!J20 | M4: المجموع | N4: النسبة% | O4: المستوى
B5: الدرجة العظمى | C5: 10 | D5: 10 | E5: 10 | F5: 10 | G5: 10 | H5: 10 | I5: 10 | J5: 10 | K5: 10 | L5: 10 | M5: 100 | N5: 100%
A6: 1 | B6: ='قاعدة الأسماء'!B5 | C6: 8 | D6: 8 | E6: 8 | F6: 7 | G6: 9 | H6: 8 | I6: 9 | J6: 8 | K6: 9 | L6: 8 | M6: =IF(COUNT(C6:L6)=0,"",SUM(C6:L6)) | N6: =IF(M6="","",M6/100) | O6: =IF(M6="","",IF(M6<50,"ضعيف",IF(M6<75,"متوسط","ممتاز")))
A7: 2 | B7: ='قاعدة الأسماء'!B6 | C7: 8 | D7: 9 | E7: 7 | F7: 8 | G7: 9 | H7: 7 | I7: 8 | J7: 7 | K7: 7 | L7: 8 | M7: =IF(COUNT(C7:L7)=0,"",SUM(C7:L7)) | N7: =IF(M7="","",M7/100) | O7: =IF(M7="","",IF(M7<50,"ضعيف",IF(M7<75,"متوسط","ممتاز")))
A8: 3 | B8: ='قاعدة الأسماء'!B7 | C8: 10 | D8: 9 | E8: 9 | F8: 8 | G8: 8 | H8: 8 | I8: 10 | J8: 8 | K8: 9 | L8: 9 | M8: =IF(COUNT(C8:L8)=0,"",SUM(C8:L8)) | N8: =IF(M8="","",M8/100) | O8: =IF(M8="","",IF(M8<50,"ضعيف",IF(M8<75,"متوسط","ممتاز")))
A9: 4 | B9: ='قاعدة الأسماء'!B8 | C9: 10 | D9: 9 | E9: 8 | F9: 7 | G9: 9 | H9: 9 | I9: 10 | J9: 8 | K9: 8 | L9: 8 | M9: =IF(COUNT(C9:L9)=0,"",SUM(C9:L9)) | N9: =IF(M9="","",M9/100) | O9: =IF(M9="","",IF(M9<50,"ضعيف",IF(M9<75,"متوسط","ممتاز")))
A10: 5 | B10: ='قاعدة الأسماء'!B9 | C10: 9 | D10: 9 | E10: 8 | F10: 8 | G10: 9 | H10: 8 | I10: 8 | J10: 9 | K10: 8 | L10: 8 | M10: =IF(COUNT(C10:L10)=0,"",SUM(C10:L10)) | N10: =IF(M10="","",M10/100) | O10: =IF(M10="","",IF(M10<50,"ضعيف",IF(M10<75,"متوسط","ممتاز")))
A11: 6 | B11: ='قاعدة الأسماء'!B10 | C11: 9 | D11: 9 | E11: 7 | F11: 8 | G11: 8 | H11: 8 | I11: 9 | J11: 9 | K11: 8 | L11: 9 | M11: =IF(COUNT(C11:L11)=0,"",SUM(C11:L11)) | N11: =IF(M11="","",M11/100) | O11: =IF(M11="","",IF(M11<50,"ضعيف",IF(M11<75,"متوسط","ممتاز")))
A12: 7 | B12: ='قاعدة الأسماء'!B11 | C12: 8 | D12: 8 | E12: 7 | F12: 7 | G12: 8 | H12: 7 | I12: 8 | J12: 8 | K12: 7 | L12: 8 | M12: =IF(COUNT(C12:L12)=0,"",SUM(C12:L12)) | N12: =IF(M12="","",M12/100) | O12: =IF(M12="","",IF(M12<50,"ضعيف",IF(M12<75,"متوسط","ممتاز")))
A13: 8 | B13: ='قاعدة الأسماء'!B12 | C13: 8 | D13: 8 | E13: 7 | F13: 7 | G13: 9 | H13: 8 | I13: 8 | J13: 8 | K13: 9 | L13: 8 | M13: =IF(COUNT(C13:L13)=0,"",SUM(C13:L13)) | N13: =IF(M13="","",M13/100) | O13: =IF(M13="","",IF(M13<50,"ضعيف",IF(M13<75,"متوسط","ممتاز")))
A14: 9 | B14: ='قاعدة الأسماء'!B13 | C14: 9 | D14: 8 | E14: 7 | F14: 7 | G14: 9 | H14: 9 | I14: 9 | J14: 7 | K14: 8 | L14: 8 | M14: =IF(COUNT(C14:L14)=0,"",SUM(C14:L14)) | N14: =IF(M14="","",M14/100) | O14: =IF(M14="","",IF(M14<50,"ضعيف",IF(M14<75,"متوسط","ممتاز")))
A15: 10 | B15: ='قاعدة الأسماء'!B14 | C15: 9 | D15: 7 | E15: 7 | F15: 8 | G15: 8 | H15: 8 | I15: 9 | J15: 7 | K15: 8 | L15: 9 | M15: =IF(COUNT(C15:L15)=0,"",SUM(C15:L15)) | N15: =IF(M15="","",M15/100) | O15: =IF(M15="","",IF(M15<50,"ضعيف",IF(M15<75,"متوسط","ممتاز")))
A16: 11 | B16: ='قاعدة الأسماء'!B15 | C16: 9 | D16: 9 | E16: 7 | F16: 7 | G16: 8 | H16: 8 | I16: 9 | J16: 8 | K16: 9 | L16: 9 | M16: =IF(COUNT(C16:L16)=0,"",SUM(C16:L16)) | N16: =IF(M16="","",M16/100) | O16: =IF(M16="","",IF(M16<50,"ضعيف",IF(M16<75,"متوسط","ممتاز")))
A17: 12 | B17: ='قاعدة الأسماء'!B16 | C17: 9 | D17: 9 | E17: 8 | F17: 9 | G17: 9 | H17: 9 | I17: 8 | J17: 9 | K17: 9 | L17: 9 | M17: =IF(COUNT(C17:L17)=0,"",SUM(C17:L17)) | N17: =IF(M17="","",M17/100) | O17: =IF(M17="","",IF(M17<50,"ضعيف",IF(M17<75,"متوسط","ممتاز")))
... A104: 99 | B104: ='قاعدة الأسماء'!B103 | C104: 5 | D104: 4 | E104: 2 | F104: 3 | G104: 3 | H104: 3 | I104: 4 | J104: 3 | K104: 3 | L104: 3 | M104: =IF(COUNT(C104:L104)=0,"",SUM(C104:L104)) | N104: =IF(M104="","",M104/100) | O104: =IF(M104="","",IF(M104<50,"ضعيف",IF(M104<75,"متوسط","ممتاز")))
A107: تحليل النتائج الفوري والرسوم البيانية – Diagnostic Analytics & Charts
B109: المؤشرات العامة
B110: متوسط الدرجات | D110: =IFERROR(AVERAGE(M6:M104),0)
B111: نسبة النجاح | D111: =IFERROR(COUNTIF(O6:O104,"<>ضعيف")/99,0)
B112: أعلى درجة | D112: =IFERROR(MAX(M6:M104),0)
B113: أدنى درجة | D113: =IFERROR(MIN(M6:M104),0)
B115: توزيع مستويات الطالبات
B116: المستوى | C116: العدد | D116: النسبة%
B117: ممتاز | C117: =COUNTIF(O6:O104,"ممتاز") | D117: =C117/99
B118: متوسط | C118: =COUNTIF(O6:O104,"متوسط") | D118: =C118/99
B119: ضعيف | C119: =COUNTIF(O6:O104,"ضعيف") | D119: =C119/99
A121: مقارنة وتحليل متوسط درجات مهارات نافس العشر
B123: المهارة | C123: المتوسط | D123: التقييم
B124: ='الواجهة الرئيسية'!B8 | C124: =IFERROR(AVERAGE(C6:C104),0) | D124: =IF(C124>=7.5,"نقطة قوة",IF(C124>=5.0,"مستوى متوسط","تحتاج دعم"))
B125: ='الواجهة الرئيسية'!D8 | C125: =IFERROR(AVERAGE(D6:D104),0) | D125: =IF(C125>=7.5,"نقطة قوة",IF(C125>=5.0,"مستوى متوسط","تحتاج دعم"))
B126: ='الواجهة الرئيسية'!F8 | C126: =IFERROR(AVERAGE(E6:E104),0) | D126: =IF(C126>=7.5,"نقطة قوة",IF(C126>=5.0,"مستوى متوسط","تحتاج دعم"))
B127: ='الواجهة الرئيسية'!H8 | C127: =IFERROR(AVERAGE(F6:F104),0) | D127: =IF(C127>=7.5,"نقطة قوة",IF(C127>=5.0,"مستوى متوسط","تحتاج دعم"))
B128: ='الواجهة الرئيسية'!J8 | C128: =IFERROR(AVERAGE(G6:G104),0) | D128: =IF(C128>=7.5,"نقطة قوة",IF(C128>=5.0,"مستوى متوسط","تحتاج دعم"))
B129: ='الواجهة الرئيسية'!B20 | C129: =IFERROR(AVERAGE(H6:H104),0) | D129: =IF(C129>=7.5,"نقطة قوة",IF(C129>=5.0,"مستوى متوسط","تحتاج دعم"))
B130: ='الواجهة الرئيسية'!D20 | C130: =IFERROR(AVERAGE(I6:I104),0) | D130: =IF(C130>=7.5,"نقطة قوة",IF(C130>=5.0,"مستوى متوسط","تحتاج دعم"))
B131: ='الواجهة الرئيسية'!F20 | C131: =IFERROR(AVERAGE(J6:J104),0) | D131: =IF(C131>=7.5,"نقطة قوة",IF(C131>=5.0,"مستوى متوسط","تحتاج دعم"))
B132: ='الواجهة الرئيسية'!H20 | C132: =IFERROR(AVERAGE(K6:K104),0) | D132: =IF(C132>=7.5,"نقطة قوة",IF(C132>=5.0,"مستوى متوسط","تحتاج دعم"))
B133: ='الواجهة الرئيسية'!J20 | C133: =IFERROR(AVERAGE(L6:L104),0) | D133: =IF(C133>=7.5,"نقطة قوة",IF(C133>=5.0,"مستوى متوسط","تحتاج دعم"))

Sheet خطط قبلية
A2: الخطط العلاجية والإثرائية – القبلي
A3: تُنشأ الخطط تلقائياً بناءً على مستوى الطالبة
A4: م | B4: اسم الطالبة | C4: المستوى | D4: نوع الخطة | E4: المهارات المستهدفة | F4: الأنشطة | G4: ملاحظات | H4: تاريخ التنفيذ
A5: 1 | B5: ='قاعدة الأسماء'!B5 | C5: ='الاختبار القبلي'!O6 | D5: =IF(C5="ضعيف","خطة علاجية",IF(C5="متوسط","خطة تطويرية","خطة إثرائية")) | E5: =IF(C5="ضعيف","تركيز على: " & 'الواجهة الرئيسية'!B8 & " و " & 'الواجهة الرئيسية'!F8,IF(C5="متوسط","تطوير: " & 'الواجهة الرئيسية'!D8 & " و " & 'الواجهة الرئيسية'!H8,"إثراء: " & 'الواجهة الرئيسية'!H20 & " و " & 'الواجهة الرئيسية'!J20)) | F5: =IF(C5="ضعيف","تدريبات مكثفة – نماذج سابقة",IF(C5="متوسط","أنشطة تفاعلية – أوراق عمل","مشاريع بحثية – مسابقات نافس"))
A6: 2 | B6: ='قاعدة الأسماء'!B6 | C6: ='الاختبار القبلي'!O7 | D6: =IF(C6="ضعيف","خطة علاجية",IF(C6="متوسط","خطة تطويرية","خطة إثرائية")) | E6: =IF(C6="ضعيف","تركيز على: " & 'الواجهة الرئيسية'!B8 & " و " & 'الواجهة الرئيسية'!F8,IF(C6="متوسط","تطوير: " & 'الواجهة الرئيسية'!D8 & " و " & 'الواجهة الرئيسية'!H8,"إثراء: " & 'الواجهة الرئيسية'!H20 & " و " & 'الواجهة الرئيسية'!J20)) | F6: =IF(C6="ضعيف","تدريبات مكثفة – نماذج سابقة",IF(C6="متوسط","أنشطة تفاعلية – أوراق عمل","مشاريع بحثية – مسابقات نافس"))
A7: 3 | B7: ='قاعدة الأسماء'!B7 | C7: ='الاختبار القبلي'!O8 | D7: =IF(C7="ضعيف","خطة علاجية",IF(C7="متوسط","خطة تطويرية","خطة إثرائية")) | E7: =IF(C7="ضعيف","تركيز على: " & 'الواجهة الرئيسية'!B8 & " و " & 'الواجهة الرئيسية'!F8,IF(C7="متوسط","تطوير: " & 'الواجهة الرئيسية'!D8 & " و " & 'الواجهة الرئيسية'!H8,"إثراء: " & 'الواجهة الرئيسية'!H20 & " و " & 'الواجهة الرئيسية'!J20)) | F7: =IF(C7="ضعيف","تدريبات مكثفة – نماذج سابقة",IF(C7="متوسط","أنشطة تفاعلية – أوراق عمل","مشاريع بحثية – مسابقات نافس"))
A8: 4 | B8: ='قاعدة الأسماء'!B8 | C8: ='الاختبار القبلي'!O9 | D8: =IF(C8="ضعيف","خطة علاجية",IF(C8="متوسط","خطة تطويرية","خطة إثرائية")) | E8: =IF(C8="ضعيف","تركيز على: " & 'الواجهة الرئيسية'!B8 & " و " & 'الواجهة الرئيسية'!F8,IF(C8="متوسط","تطوير: " & 'الواجهة الرئيسية'!D8 & " و " & 'الواجهة الرئيسية'!H8,"إثراء: " & 'الواجهة الرئيسية'!H20 & " و " & 'الواجهة الرئيسية'!J20)) | F8: =IF(C8="ضعيف","تدريبات مكثفة – نماذج سابقة",IF(C8="متوسط","أنشطة تفاعلية – أوراق عمل","مشاريع بحثية – مسابقات نافس"))
A9: 5 | B9: ='قاعدة الأسماء'!B9 | C9: ='الاختبار القبلي'!O10 | D9: =IF(C9="ضعيف","خطة علاجية",IF(C9="متوسط","خطة تطويرية","خطة إثرائية")) | E9: =IF(C9="ضعيف","تركيز على: " & 'الواجهة الرئيسية'!B8 & " و " & 'الواجهة الرئيسية'!F8,IF(C9="متوسط","تطوير: " & 'الواجهة الرئيسية'!D8 & " و " & 'الواجهة الرئيسية'!H8,"إثراء: " & 'الواجهة الرئيسية'!H20 & " و " & 'الواجهة الرئيسية'!J20)) | F9: =IF(C9="ضعيف","تدريبات مكثفة – نماذج سابقة",IF(C9="متوسط","أنشطة تفاعلية – أوراق عمل","مشاريع بحثية – مسابقات نافس"))
A10: 6 | B10: ='قاعدة الأسماء'!B10 | C10: ='الاختبار القبلي'!O11 | D10: =IF(C10="ضعيف","خطة علاجية",IF(C10="متوسط","خطة تطويرية","خطة إثرائية")) | E10: =IF(C10="ضعيف","تركيز على: " & 'الواجهة الرئيسية'!B8 & " و " & 'الواجهة الرئيسية'!F8,IF(C10="متوسط","تطوير: " & 'الواجهة الرئيسية'!D8 & " و " & 'الواجهة الرئيسية'!H8,"إثراء: " & 'الواجهة الرئيسية'!H20 & " و " & 'الواجهة الرئيسية'!J20)) | F10: =IF(C10="ضعيف","تدريبات مكثفة – نماذج سابقة",IF(C10="متوسط","أنشطة تفاعلية – أوراق عمل","مشاريع بحثية – مسابقات نافس"))
A11: 7 | B11: ='قاعدة الأسماء'!B11 | C11: ='الاختبار القبلي'!O12 | D11: =IF(C11="ضعيف","خطة علاجية",IF(C11="متوسط","خطة تطويرية","خطة إثرائية")) | E11: =IF(C11="ضعيف","تركيز على: " & 'الواجهة الرئيسية'!B8 & " و " & 'الواجهة الرئيسية'!F8,IF(C11="متوسط","تطوير: " & 'الواجهة الرئيسية'!D8 & " و " & 'الواجهة الرئيسية'!H8,"إثراء: " & 'الواجهة الرئيسية'!H20 & " و " & 'الواجهة الرئيسية'!J20)) | F11: =IF(C11="ضعيف","تدريبات مكثفة – نماذج سابقة",IF(C11="متوسط","أنشطة تفاعلية – أوراق عمل","مشاريع بحثية – مسابقات نافس"))
A12: 8 | B12: ='قاعدة الأسماء'!B12 | C12: ='الاختبار القبلي'!O13 | D12: =IF(C12="ضعيف","خطة علاجية",IF(C12="متوسط","خطة تطويرية","خطة إثرائية")) | E12: =IF(C12="ضعيف","تركيز على: " & 'الواجهة الرئيسية'!B8 & " و " & 'الواجهة الرئيسية'!F8,IF(C12="متوسط","تطوير: " & 'الواجهة الرئيسية'!D8 & " و " & 'الواجهة الرئيسية'!H8,"إثراء: " & 'الواجهة الرئيسية'!H20 & " و " & 'الواجهة الرئيسية'!J20)) | F12: =IF(C12="ضعيف","تدريبات مكثفة – نماذج سابقة",IF(C12="متوسط","أنشطة تفاعلية – أوراق عمل","مشاريع بحثية – مسابقات نافس"))
A13: 9 | B13: ='قاعدة الأسماء'!B13 | C13: ='الاختبار القبلي'!O14 | D13: =IF(C13="ضعيف","خطة علاجية",IF(C13="متوسط","خطة تطويرية","خطة إثرائية")) | E13: =IF(C13="ضعيف","تركيز على: " & 'الواجهة الرئيسية'!B8 & " و " & 'الواجهة الرئيسية'!F8,IF(C13="متوسط","تطوير: " & 'الواجهة الرئيسية'!D8 & " و " & 'الواجهة الرئيسية'!H8,"إثراء: " & 'الواجهة الرئيسية'!H20 & " و " & 'الواجهة الرئيسية'!J20)) | F13: =IF(C13="ضعيف","تدريبات مكثفة – نماذج سابقة",IF(C13="متوسط","أنشطة تفاعلية – أوراق عمل","مشاريع بحثية – مسابقات نافس"))
A14: 10 | B14: ='قاعدة الأسماء'!B14 | C14: ='الاختبار القبلي'!O15 | D14: =IF(C14="ضعيف","خطة علاجية",IF(C14="متوسط","خطة تطويرية","خطة إثرائية")) | E14: =IF(C14="ضعيف","تركيز على: " & 'الواجهة الرئيسية'!B8 & " و " & 'الواجهة الرئيسية'!F8,IF(C14="متوسط","تطوير: " & 'الواجهة الرئيسية'!D8 & " و " & 'الواجهة الرئيسية'!H8,"إثراء: " & 'الواجهة الرئيسية'!H20 & " و " & 'الواجهة الرئيسية'!J20)) | F14: =IF(C14="ضعيف","تدريبات مكثفة – نماذج سابقة",IF(C14="متوسط","أنشطة تفاعلية – أوراق عمل","مشاريع بحثية – مسابقات نافس"))
A15: 11 | B15: ='قاعدة الأسماء'!B15 | C15: ='الاختبار القبلي'!O16 | D15: =IF(C15="ضعيف","خطة علاجية",IF(C15="متوسط","خطة تطويرية","خطة إثرائية")) | E15: =IF(C15="ضعيف","تركيز على: " & 'الواجهة الرئيسية'!B8 & " و " & 'الواجهة الرئيسية'!F8,IF(C15="متوسط","تطوير: " & 'الواجهة الرئيسية'!D8 & " و " & 'الواجهة الرئيسية'!H8,"إثراء: " & 'الواجهة الرئيسية'!H20 & " و " & 'الواجهة الرئيسية'!J20)) | F15: =IF(C15="ضعيف","تدريبات مكثفة – نماذج سابقة",IF(C15="متوسط","أنشطة تفاعلية – أوراق عمل","مشاريع بحثية – مسابقات نافس"))
A16: 12 | B16: ='قاعدة الأسماء'!B16 | C16: ='الاختبار القبلي'!O17 | D16: =IF(C16="ضعيف","خطة علاجية",IF(C16="متوسط","خطة تطويرية","خطة إثرائية")) | E16: =IF(C16="ضعيف","تركيز على: " & 'الواجهة الرئيسية'!B8 & " و " & 'الواجهة الرئيسية'!F8,IF(C16="متوسط","تطوير: " & 'الواجهة الرئيسية'!D8 & " و " & 'الواجهة الرئيسية'!H8,"إثراء: " & 'الواجهة الرئيسية'!H20 & " و " & 'الواجهة الرئيسية'!J20)) | F16: =IF(C16="ضعيف","تدريبات مكثفة – نماذج سابقة",IF(C16="متوسط","أنشطة تفاعلية – أوراق عمل","مشاريع بحثية – مسابقات نافس"))
A17: 13 | B17: ='قاعدة الأسماء'!B17 | C17: ='الاختبار القبلي'!O18 | D17: =IF(C17="ضعيف","خطة علاجية",IF(C17="متوسط","خطة تطويرية","خطة إثرائية")) | E17: =IF(C17="ضعيف","تركيز على: " & 'الواجهة الرئيسية'!B8 & " و " & 'الواجهة الرئيسية'!F8,IF(C17="متوسط","تطوير: " & 'الواجهة الرئيسية'!D8 & " و " & 'الواجهة الرئيسية'!H8,"إثراء: " & 'الواجهة الرئيسية'!H20 & " و " & 'الواجهة الرئيسية'!J20)) | F17: =IF(C17="ضعيف","تدريبات مكثفة – نماذج سابقة",IF(C17="متوسط","أنشطة تفاعلية – أوراق عمل","مشاريع بحثية – مسابقات نافس"))
A18: 14 | B18: ='قاعدة الأسماء'!B18 | C18: ='الاختبار القبلي'!O19 | D18: =IF(C18="ضعيف","خطة علاجية",IF(C18="متوسط","خطة تطويرية","خطة إثرائية")) | E18: =IF(C18="ضعيف","تركيز على: " & 'الواجهة الرئيسية'!B8 & " و " & 'الواجهة الرئيسية'!F8,IF(C18="متوسط","تطوير: " & 'الواجهة الرئيسية'!D8 & " و " & 'الواجهة الرئيسية'!H8,"إثراء: " & 'الواجهة الرئيسية'!H20 & " و " & 'الواجهة الرئيسية'!J20)) | F18: =IF(C18="ضعيف","تدريبات مكثفة – نماذج سابقة",IF(C18="متوسط","أنشطة تفاعلية – أوراق عمل","مشاريع بحثية – مسابقات نافس"))
A19: 15 | B19: ='قاعدة الأسماء'!B19 | C19: ='الاختبار القبلي'!O20 | D19: =IF(C19="ضعيف","خطة علاجية",IF(C19="متوسط","خطة تطويرية","خطة إثرائية")) | E19: =IF(C19="ضعيف","تركيز على: " & 'الواجهة الرئيسية'!B8 & " و " & 'الواجهة الرئيسية'!F8,IF(C19="متوسط","تطوير: " & 'الواجهة الرئيسية'!D8 & " و " & 'الواجهة الرئيسية'!H8,"إثراء: " & 'الواجهة الرئيسية'!H20 & " و " & 'الواجهة الرئيسية'!J20)) | F19: =IF(C19="ضعيف","تدريبات مكثفة – نماذج سابقة",IF(C19="متوسط","أنشطة تفاعلية – أوراق عمل","مشاريع بحثية – مسابقات نافس"))
A20: 16 | B20: ='قاعدة الأسماء'!B20 | C20: ='الاختبار القبلي'!O21 | D20: =IF(C20="ضعيف","خطة علاجية",IF(C20="متوسط","خطة تطويرية","خطة إثرائية")) | E20: =IF(C20="ضعيف","تركيز على: " & 'الواجهة الرئيسية'!B8 & " و " & 'الواجهة الرئيسية'!F8,IF(C20="متوسط","تطوير: " & 'الواجهة الرئيسية'!D8 & " و " & 'الواجهة الرئيسية'!H8,"إثراء: " & 'الواجهة الرئيسية'!H20 & " و " & 'الواجهة الرئيسية'!J20)) | F20: =IF(C20="ضعيف","تدريبات مكثفة – نماذج سابقة",IF(C20="متوسط","أنشطة تفاعلية – أوراق عمل","مشاريع بحثية – مسابقات نافس"))
A21: 17 | B21: ='قاعدة الأسماء'!B21 | C21: ='الاختبار القبلي'!O22 | D21: =IF(C21="ضعيف","خطة علاجية",IF(C21="متوسط","خطة تطويرية","خطة إثرائية")) | E21: =IF(C21="ضعيف","تركيز على: " & 'الواجهة الرئيسية'!B8 & " و " & 'الواجهة الرئيسية'!F8,IF(C21="متوسط","تطوير: " & 'الواجهة الرئيسية'!D8 & " و " & 'الواجهة الرئيسية'!H8,"إثراء: " & 'الواجهة الرئيسية'!H20 & " و " & 'الواجهة الرئيسية'!J20)) | F21: =IF(C21="ضعيف","تدريبات مكثفة – نماذج سابقة",IF(C21="متوسط","أنشطة تفاعلية – أوراق عمل","مشاريع بحثية – مسابقات نافس"))
A22: 18 | B22: ='قاعدة الأسماء'!B22 | C22: ='الاختبار القبلي'!O23 | D22: =IF(C22="ضعيف","خطة علاجية",IF(C22="متوسط","خطة تطويرية","خطة إثرائية")) | E22: =IF(C22="ضعيف","تركيز على: " & 'الواجهة الرئيسية'!B8 & " و " & 'الواجهة الرئيسية'!F8,IF(C22="متوسط","تطوير: " & 'الواجهة الرئيسية'!D8 & " و " & 'الواجهة الرئيسية'!H8,"إثراء: " & 'الواجهة الرئيسية'!H20 & " و " & 'الواجهة الرئيسية'!J20)) | F22: =IF(C22="ضعيف","تدريبات مكثفة – نماذج سابقة",IF(C22="متوسط","أنشطة تفاعلية – أوراق عمل","مشاريع بحثية – مسابقات نافس"))
A23: 19 | B23: ='قاعدة الأسماء'!B23 | C23: ='الاختبار القبلي'!O24 | D23: =IF(C23="ضعيف","خطة علاجية",IF(C23="متوسط","خطة تطويرية","خطة إثرائية")) | E23: =IF(C23="ضعيف","تركيز على: " & 'الواجهة الرئيسية'!B8 & " و " & 'الواجهة الرئيسية'!F8,IF(C23="متوسط","تطوير: " & 'الواجهة الرئيسية'!D8 & " و " & 'الواجهة الرئيسية'!H8,"إثراء: " & 'الواجهة الرئيسية'!H20 & " و " & 'الواجهة الرئيسية'!J20)) | F23: =IF(C23="ضعيف","تدريبات مكثفة – نماذج سابقة",IF(C23="متوسط","أنشطة تفاعلية – أوراق عمل","مشاريع بحثية – مسابقات نافس"))
A24: 20 | B24: ='قاعدة الأسماء'!B24 | C24: ='الاختبار القبلي'!O25 | D24: =IF(C24="ضعيف","خطة علاجية",IF(C24="متوسط","خطة تطويرية","خطة إثرائية")) | E24: =IF(C24="ضعيف","تركيز على: " & 'الواجهة الرئيسية'!B8 & " و " & 'الواجهة الرئيسية'!F8,IF(C24="متوسط","تطوير: " & 'الواجهة الرئيسية'!D8 & " و " & 'الواجهة الرئيسية'!H8,"إثراء: " & 'الواجهة الرئيسية'!H20 & " و " & 'الواجهة الرئيسية'!J20)) | F24: =IF(C24="ضعيف","تدريبات مكثفة – نماذج سابقة",IF(C24="متوسط","أنشطة تفاعلية – أوراق عمل","مشاريع بحثية – مسابقات نافس"))
A25: 21 | B25: ='قاعدة الأسماء'!B25 | C25: ='الاختبار القبلي'!O26 | D25: =IF(C25="ضعيف","خطة علاجية",IF(C25="متوسط","خطة تطويرية","خطة إثرائية")) | E25: =IF(C25="ضعيف","تركيز على: " & 'الواجهة الرئيسية'!B8 & " و " & 'الواجهة الرئيسية'!F8,IF(C25="متوسط","تطوير: " & 'الواجهة الرئيسية'!D8 & " و " & 'الواجهة الرئيسية'!H8,"إثراء: " & 'الواجهة الرئيسية'!H20 & " و " & 'الواجهة الرئيسية'!J20)) | F25: =IF(C25="ضعيف","تدريبات مكثفة – نماذج سابقة",IF(C25="متوسط","أنشطة تفاعلية – أوراق عمل","مشاريع بحثية – مسابقات نافس"))
A26: 22 | B26: ='قاعدة الأسماء'!B26 | C26: ='الاختبار القبلي'!O27 | D26: =IF(C26="ضعيف","خطة علاجية",IF(C26="متوسط","خطة تطويرية","خطة إثرائية")) | E26: =IF(C26="ضعيف","تركيز على: " & 'الواجهة الرئيسية'!B8 & " و " & 'الواجهة الرئيسية'!F8,IF(C26="متوسط","تطوير: " & 'الواجهة الرئيسية'!D8 & " و " & 'الواجهة الرئيسية'!H8,"إثراء: " & 'الواجهة الرئيسية'!H20 & " و " & 'الواجهة الرئيسية'!J20)) | F26: =IF(C26="ضعيف","تدريبات مكثفة – نماذج سابقة",IF(C26="متوسط","أنشطة تفاعلية – أوراق عمل","مشاريع بحثية – مسابقات نافس"))
A27: 23 | B27: ='قاعدة الأسماء'!B27 | C27: ='الاختبار القبلي'!O28 | D27: =IF(C27="ضعيف","خطة علاجية",IF(C27="متوسط","خطة تطويرية","خطة إثرائية")) | E27: =IF(C27="ضعيف","تركيز على: " & 'الواجهة الرئيسية'!B8 & " و " & 'الواجهة الرئيسية'!F8,IF(C27="متوسط","تطوير: " & 'الواجهة الرئيسية'!D8 & " و " & 'الواجهة الرئيسية'!H8,"إثراء: " & 'الواجهة الرئيسية'!H20 & " و " & 'الواجهة الرئيسية'!J20)) | F27: =IF(C27="ضعيف","تدريبات مكثفة – نماذج سابقة",IF(C27="متوسط","أنشطة تفاعلية – أوراق عمل","مشاريع بحثية – مسابقات نافس"))
A28: 24 | B28: ='قاعدة الأسماء'!B28 | C28: ='الاختبار القبلي'!O29 | D28: =IF(C28="ضعيف","خطة علاجية",IF(C28="متوسط","خطة تطويرية","خطة إثرائية")) | E28: =IF(C28="ضعيف","تركيز على: " & 'الواجهة الرئيسية'!B8 & " و " & 'الواجهة الرئيسية'!F8,IF(C28="متوسط","تطوير: " & 'الواجهة الرئيسية'!D8 & " و " & 'الواجهة الرئيسية'!H8,"إثراء: " & 'الواجهة الرئيسية'!H20 & " و " & 'الواجهة الرئيسية'!J20)) | F28: =IF(C28="ضعيف","تدريبات مكثفة – نماذج سابقة",IF(C28="متوسط","أنشطة تفاعلية – أوراق عمل","مشاريع بحثية – مسابقات نافس"))
A29: 25 | B29: ='قاعدة الأسماء'!B29 | C29: ='الاختبار القبلي'!O30 | D29: =IF(C29="ضعيف","خطة علاجية",IF(C29="متوسط","خطة تطويرية","خطة إثرائية")) | E29: =IF(C29="ضعيف","تركيز على: " & 'الواجهة الرئيسية'!B8 & " و " & 'الواجهة الرئيسية'!F8,IF(C29="متوسط","تطوير: " & 'الواجهة الرئيسية'!D8 & " و " & 'الواجهة الرئيسية'!H8,"إثراء: " & 'الواجهة الرئيسية'!H20 & " و " & 'الواجهة الرئيسية'!J20)) | F29: =IF(C29="ضعيف","تدريبات مكثفة – نماذج سابقة",IF(C29="متوسط","أنشطة تفاعلية – أوراق عمل","مشاريع بحثية – مسابقات نافس"))
A30: 26 | B30: ='قاعدة الأسماء'!B30 | C30: ='الاختبار القبلي'!O31 | D30: =IF(C30="ضعيف","خطة علاجية",IF(C30="متوسط","خطة تطويرية","خطة إثرائية")) | E30: =IF(C30="ضعيف","تركيز على: " & 'الواجهة الرئيسية'!B8 & " و " & 'الواجهة الرئيسية'!F8,IF(C30="متوسط","تطوير: " & 'الواجهة الرئيسية'!D8 & " و " & 'الواجهة الرئيسية'!H8,"إثراء: " & 'الواجهة الرئيسية'!H20 & " و " & 'الواجهة الرئيسية'!J20)) | F30: =IF(C30="ضعيف","تدريبات مكثفة – نماذج سابقة",IF(C30="متوسط","أنشطة تفاعلية – أوراق عمل","مشاريع بحثية – مسابقات نافس"))
A31: 27 | B31: ='قاعدة الأسماء'!B31 | C31: ='الاختبار القبلي'!O32 | D31: =IF(C31="ضعيف","خطة علاجية",IF(C31="متوسط","خطة تطويرية","خطة إثرائية")) | E31: =IF(C31="ضعيف","تركيز على: " & 'الواجهة الرئيسية'!B8 & " و " & 'الواجهة الرئيسية'!F8,IF(C31="متوسط","تطوير: " & 'الواجهة الرئيسية'!D8 & " و " & 'الواجهة الرئيسية'!H8,"إثراء: " & 'الواجهة الرئيسية'!H20 & " و " & 'الواجهة الرئيسية'!J20)) | F31: =IF(C31="ضعيف","تدريبات مكثفة – نماذج سابقة",IF(C31="متوسط","أنشطة تفاعلية – أوراق عمل","مشاريع بحثية – مسابقات نافس"))
A32: 28 | B32: ='قاعدة الأسماء'!B32 | C32: ='الاختبار القبلي'!O33 | D32: =IF(C32="ضعيف","خطة علاجية",IF(C32="متوسط","خطة تطويرية","خطة إثرائية")) | E32: =IF(C32="ضعيف","تركيز على: " & 'الواجهة الرئيسية'!B8 & " و " & 'الواجهة الرئيسية'!F8,IF(C32="متوسط","تطوير: " & 'الواجهة الرئيسية'!D8 & " و " & 'الواجهة الرئيسية'!H8,"إثراء: " & 'الواجهة الرئيسية'!H20 & " و " & 'الواجهة الرئيسية'!J20)) | F32: =IF(C32="ضعيف","تدريبات مكثفة – نماذج سابقة",IF(C32="متوسط","أنشطة تفاعلية – أوراق عمل","مشاريع بحثية – مسابقات نافس"))
A33: 29 | B33: ='قاعدة الأسماء'!B33 | C33: ='الاختبار القبلي'!O34 | D33: =IF(C33="ضعيف","خطة علاجية",IF(C33="متوسط","خطة تطويرية","خطة إثرائية")) | E33: =IF(C33="ضعيف","تركيز على: " & 'الواجهة الرئيسية'!B8 & " و " & 'الواجهة الرئيسية'!F8,IF(C33="متوسط","تطوير: " & 'الواجهة الرئيسية'!D8 & " و " & 'الواجهة الرئيسية'!H8,"إثراء: " & 'الواجهة الرئيسية'!H20 & " و " & 'الواجهة الرئيسية'!J20)) | F33: =IF(C33="ضعيف","تدريبات مكثفة – نماذج سابقة",IF(C33="متوسط","أنشطة تفاعلية – أوراق عمل","مشاريع بحثية – مسابقات نافس"))
A34: 30 | B34: ='قاعدة الأسماء'!B34 | C34: ='الاختبار القبلي'!O35 | D34: =IF(C34="ضعيف","خطة علاجية",IF(C34="متوسط","خطة تطويرية","خطة إثرائية")) | E34: =IF(C34="ضعيف","تركيز على: " & 'الواجهة الرئيسية'!B8 & " و " & 'الواجهة الرئيسية'!F8,IF(C34="متوسط","تطوير: " & 'الواجهة الرئيسية'!D8 & " و " & 'الواجهة الرئيسية'!H8,"إثراء: " & 'الواجهة الرئيسية'!H20 & " و " & 'الواجهة الرئيسية'!J20)) | F34: =IF(C34="ضعيف","تدريبات مكثفة – نماذج سابقة",IF(C34="متوسط","أنشطة تفاعلية – أوراق عمل","مشاريع بحثية – مسابقات نافس"))
A35: 31 | B35: ='قاعدة الأسماء'!B35 | C35: ='الاختبار القبلي'!O36 | D35: =IF(C35="ضعيف","خطة علاجية",IF(C35="متوسط","خطة تطويرية","خطة إثرائية")) | E35: =IF(C35="ضعيف","تركيز على: " & 'الواجهة الرئيسية'!B8 & " و " & 'الواجهة الرئيسية'!F8,IF(C35="متوسط","تطوير: " & 'الواجهة الرئيسية'!D8 & " و " & 'الواجهة الرئيسية'!H8,"إثراء: " & 'الواجهة الرئيسية'!H20 & " و " & 'الواجهة الرئيسية'!J20)) | F35: =IF(C35="ضعيف","تدريبات مكثفة – نماذج سابقة",IF(C35="متوسط","أنشطة تفاعلية – أوراق عمل","مشاريع بحثية – مسابقات نافس"))
A36: 32 | B36: ='قاعدة الأسماء'!B36 | C36: ='الاختبار القبلي'!O37 | D36: =IF(C36="ضعيف","خطة علاجية",IF(C36="متوسط","خطة تطويرية","خطة إثرائية")) | E36: =IF(C36="ضعيف","تركيز على: " & 'الواجهة الرئيسية'!B8 & " و " & 'الواجهة الرئيسية'!F8,IF(C36="متوسط","تطوير: " & 'الواجهة الرئيسية'!D8 & " و " & 'الواجهة الرئيسية'!H8,"إثراء: " & 'الواجهة الرئيسية'!H20 & " و " & 'الواجهة الرئيسية'!J20)) | F36: =IF(C36="ضعيف","تدريبات مكثفة – نماذج سابقة",IF(C36="متوسط","أنشطة تفاعلية – أوراق عمل","مشاريع بحثية – مسابقات نافس"))
A37: 33 | B37: ='قاعدة الأسماء'!B37 | C37: ='الاختبار القبلي'!O38 | D37: =IF(C37="ضعيف","خطة علاجية",IF(C37="متوسط","خطة تطويرية","خطة إثرائية")) | E37: =IF(C37="ضعيف","تركيز على: " & 'الواجهة الرئيسية'!B8 & " و " & 'الواجهة الرئيسية'!F8,IF(C37="متوسط","تطوير: " & 'الواجهة الرئيسية'!D8 & " و " & 'الواجهة الرئيسية'!H8,"إثراء: " & 'الواجهة الرئيسية'!H20 & " و " & 'الواجهة الرئيسية'!J20)) | F37: =IF(C37="ضعيف","تدريبات مكثفة – نماذج سابقة",IF(C37="متوسط","أنشطة تفاعلية – أوراق عمل","مشاريع بحثية – مسابقات نافس"))
A38: 34 | B38: ='قاعدة الأسماء'!B38 | C38: ='الاختبار القبلي'!O39 | D38: =IF(C38="ضعيف","خطة علاجية",IF(C38="متوسط","خطة تطويرية","خطة إثرائية")) | E38: =IF(C38="ضعيف","تركيز على: " & 'الواجهة الرئيسية'!B8 & " و " & 'الواجهة الرئيسية'!F8,IF(C38="متوسط","تطوير: " & 'الواجهة الرئيسية'!D8 & " و " & 'الواجهة الرئيسية'!H8,"إثراء: " & 'الواجهة الرئيسية'!H20 & " و " & 'الواجهة الرئيسية'!J20)) | F38: =IF(C38="ضعيف","تدريبات مكثفة – نماذج سابقة",IF(C38="متوسط","أنشطة تفاعلية – أوراق عمل","مشاريع بحثية – مسابقات نافس"))
A39: 35 | B39: ='قاعدة الأسماء'!B39 | C39: ='الاختبار القبلي'!O40 | D39: =IF(C39="ضعيف","خطة علاجية",IF(C39="متوسط","خطة تطويرية","خطة إثرائية")) | E39: =IF(C39="ضعيف","تركيز على: " & 'الواجهة الرئيسية'!B8 & " و " & 'الواجهة الرئيسية'!F8,IF(C39="متوسط","تطوير: " & 'الواجهة الرئيسية'!D8 & " و " & 'الواجهة الرئيسية'!H8,"إثراء: " & 'الواجهة الرئيسية'!H20 & " و " & 'الواجهة الرئيسية'!J20)) | F39: =IF(C39="ضعيف","تدريبات مكثفة – نماذج سابقة",IF(C39="متوسط","أنشطة تفاعلية – أوراق عمل","مشاريع بحثية – مسابقات نافس"))
A40: 36 | B40: ='قاعدة الأسماء'!B40 | C40: ='الاختبار القبلي'!O41 | D40: =IF(C40="ضعيف","خطة علاجية",IF(C40="متوسط","خطة تطويرية","خطة إثرائية")) | E40: =IF(C40="ضعيف","تركيز على: " & 'الواجهة الرئيسية'!B8 & " و " & 'الواجهة الرئيسية'!F8,IF(C40="متوسط","تطوير: " & 'الواجهة الرئيسية'!D8 & " و " & 'الواجهة الرئيسية'!H8,"إثراء: " & 'الواجهة الرئيسية'!H20 & " و " & 'الواجهة الرئيسية'!J20)) | F40: =IF(C40="ضعيف","تدريبات مكثفة – نماذج سابقة",IF(C40="متوسط","أنشطة تفاعلية – أوراق عمل","مشاريع بحثية – مسابقات نافس"))
A41: 37 | B41: ='قاعدة الأسماء'!B41 | C41: ='الاختبار القبلي'!O42 | D41: =IF(C41="ضعيف","خطة علاجية",IF(C41="متوسط","خطة تطويرية","خطة إثرائية")) | E41: =IF(C41="ضعيف","تركيز على: " & 'الواجهة الرئيسية'!B8 & " و " & 'الواجهة الرئيسية'!F8,IF(C41="متوسط","تطوير: " & 'الواجهة الرئيسية'!D8 & " و " & 'الواجهة الرئيسية'!H8,"إثراء: " & 'الواجهة الرئيسية'!H20 & " و " & 'الواجهة الرئيسية'!J20)) | F41: =IF(C41="ضعيف","تدريبات مكثفة – نماذج سابقة",IF(C41="متوسط","أنشطة تفاعلية – أوراق عمل","مشاريع بحثية – مسابقات نافس"))
...

Sheet التدريبات
A2: تدريبات نافس والخطة التدريبية لرفع نواتج التعلم
A3: اختبارات نافس التدريبية | الخطة التدريبية | تتبع التقدم
A4: م | B4: اسم الطالبة | C4: ="تدريب 1 " & CHAR(10) & 'الواجهة الرئيسية'!B8 | D4: ="تدريب 2 " & CHAR(10) & 'الواجهة الرئيسية'!D8 | E4: ="تدريب 3 " & CHAR(10) & 'الواجهة الرئيسية'!F8 | F4: ="تدريب 4 " & CHAR(10) & 'الواجهة الرئيسية'!H8 | G4: ="تدريب 5 " & CHAR(10) & 'الواجهة الرئيسية'!J8 | H4: ="تدريب 6 " & CHAR(10) & 'الواجهة الرئيسية'!B20 | I4: ="تدريب 7 " & CHAR(10) & 'الواجهة الرئيسية'!D20 | J4: ="تدريب 8 " & CHAR(10) & 'الواجهة الرئيسية'!F20 | K4: ="تدريب 9 " & CHAR(10) & 'الواجهة الرئيسية'!H20 | L4: ="تدريب 10 " & CHAR(10) & 'الواجهة الرئيسية'!J20 | M4: المجموع | N4: التقدم
A5: 1 | B5: ='قاعدة الأسماء'!B5 | C5: 9 | D5: 8 | E5: 8 | F5: 7 | G5: 9 | H5: 10 | I5: 9 | J5: 9 | K5: 10 | L5: 9 | M5: =IF(COUNT(C5:L5)=0,"",SUM(C5:L5)) | N5: =IF(M5="","",IF(M5<50,"يحتاج دعماً",IF(M5<75,"جيد","ممتاز")))
A6: 2 | B6: ='قاعدة الأسماء'!B6 | C6: 10 | D6: 10 | E6: 8 | F6: 8 | G6: 9 | H6: 9 | I6: 9 | J6: 7 | K6: 8 | L6: 9 | M6: =IF(COUNT(C6:L6)=0,"",SUM(C6:L6)) | N6: =IF(M6="","",IF(M6<50,"يحتاج دعماً",IF(M6<75,"جيد","ممتاز")))
A7: 3 | B7: ='قاعدة الأسماء'!B7 | C7: 10 | D7: 9 | E7: 10 | F7: 10 | G7: 9 | H7: 10 | I7: 10 | J7: 8 | K7: 10 | L7: 10 | M7: =IF(COUNT(C7:L7)=0,"",SUM(C7:L7)) | N7: =IF(M7="","",IF(M7<50,"يحتاج دعماً",IF(M7<75,"جيد","ممتاز")))
A8: 4 | B8: ='قاعدة الأسماء'!B8 | C8: 10 | D8: 10 | E8: 10 | F8: 8 | G8: 9 | H8: 10 | I8: 10 | J8: 8 | K8: 9 | L8: 10 | M8: =IF(COUNT(C8:L8)=0,"",SUM(C8:L8)) | N8: =IF(M8="","",IF(M8<50,"يحتاج دعماً",IF(M8<75,"جيد","ممتاز")))
A9: 5 | B9: ='قاعدة الأسماء'!B9 | C9: 10 | D9: 10 | E9: 9 | F9: 9 | G9: 10 | H9: 9 | I9: 8 | J9: 10 | K9: 10 | L9: 10 | M9: =IF(COUNT(C9:L9)=0,"",SUM(C9:L9)) | N9: =IF(M9="","",IF(M9<50,"يحتاج دعماً",IF(M9<75,"جيد","ممتاز")))
A10: 6 | B10: ='قاعدة الأسماء'!B10 | C10: 9 | D10: 10 | E10: 7 | F10: 8 | G10: 10 | H10: 10 | I10: 9 | J10: 9 | K10: 10 | L10: 9 | M10: =IF(COUNT(C10:L10)=0,"",SUM(C10:L10)) | N10: =IF(M10="","",IF(M10<50,"يحتاج دعماً",IF(M10<75,"جيد","ممتاز")))
A11: 7 | B11: ='قاعدة الأسماء'!B11 | C11: 10 | D11: 10 | E11: 7 | F11: 8 | G11: 9 | H11: 8 | I11: 9 | J11: 9 | K11: 7 | L11: 9 | M11: =IF(COUNT(C11:L11)=0,"",SUM(C11:L11)) | N11: =IF(M11="","",IF(M11<50,"يحتاج دعماً",IF(M11<75,"جيد","ممتاز")))
A12: 8 | B12: ='قاعدة الأسماء'!B12 | C12: 9 | D12: 9 | E12: 7 | F12: 8 | G12: 10 | H12: 9 | I12: 9 | J12: 9 | K12: 10 | L12: 9 | M12: =IF(COUNT(C12:L12)=0,"",SUM(C12:L12)) | N12: =IF(M12="","",IF(M12<50,"يحتاج دعماً",IF(M12<75,"جيد","ممتاز")))
A13: 9 | B13: ='قاعدة الأسماء'!B13 | C13: 10 | D13: 10 | E13: 8 | F13: 9 | G13: 9 | H13: 10 | I13: 10 | J13: 8 | K13: 9 | L13: 10 | M13: =IF(COUNT(C13:L13)=0,"",SUM(C13:L13)) | N13: =IF(M13="","",IF(M13<50,"يحتاج دعماً",IF(M13<75,"جيد","ممتاز")))
A14: 10 | B14: ='قاعدة الأسماء'!B14 | C14: 10 | D14: 8 | E14: 7 | F14: 9 | G14: 9 | H14: 10 | I14: 10 | J14: 8 | K14: 9 | L14: 10 | M14: =IF(COUNT(C14:L14)=0,"",SUM(C14:L14)) | N14: =IF(M14="","",IF(M14<50,"يحتاج دعماً",IF(M14<75,"جيد","ممتاز")))
A15: 11 | B15: ='قاعدة الأسماء'!B15 | C15: 10 | D15: 9 | E15: 7 | F15: 8 | G15: 9 | H15: 8 | I15: 10 | J15: 9 | K15: 10 | L15: 10 | M15: =IF(COUNT(C15:L15)=0,"",SUM(C15:L15)) | N15: =IF(M15="","",IF(M15<50,"يحتاج دعماً",IF(M15<75,"جيد","ممتاز")))
A16: 12 | B16: ='قاعدة الأسماء'!B16 | C16: 10 | D16: 10 | E16: 9 | F16: 10 | G16: 10 | H16: 10 | I16: 9 | J16: 9 | K16: 10 | L16: 10 | M16: =IF(COUNT(C16:L16)=0,"",SUM(C16:L16)) | N16: =IF(M16="","",IF(M16<50,"يحتاج دعماً",IF(M16<75,"جيد","ممتاز")))
... A103: 99 | B103: ='قاعدة الأسماء'!B103 | C103: 6 | D103: 4 | E103: 2 | F103: 4 | G103: 4 | H103: 4 | I103: 5 | J103: 4 | K103: 4 | L103: 3 | M103: =IF(COUNT(C103:L103)=0,"",SUM(C103:L103)) | N103: =IF(M103="","",IF(M103<50,"يحتاج دعماً",IF(M103<75,"جيد","ممتاز")))
A106: الخطة التدريبية الأسبوعية
A107: الأسبوع | B107: المهارة | C107: نوع النشاط | D107: الأدوات | E107: التوقيت | F107: المسؤول | G107: ملاحظات
A108: الأسبوع 1 | B108: ='الواجهة الرئيسية'!B8 | C108: ورشة عمل تفاعلية | D108: أوراق عمل | E108: 45 دقيقة
A109: الأسبوع 2 | B109: ='الواجهة الرئيسية'!D8 | C109: ورشة عمل تفاعلية | D109: أوراق عمل | E109: 45 دقيقة
A110: الأسبوع 3 | B110: ='الواجهة الرئيسية'!F8 | C110: ورشة عمل تفاعلية | D110: أوراق عمل | E110: 45 دقيقة
A111: الأسبوع 4 | B111: ='الواجهة الرئيسية'!H8 | C111: ورشة عمل تفاعلية | D111: أوراق عمل | E111: 45 دقيقة
A112: الأسبوع 5 | B112: ='الواجهة الرئيسية'!J8 | C112: ورشة عمل تفاعلية | D112: أوراق عمل | E112: 45 دقيقة
A113: الأسبوع 6 | B113: ='الواجهة الرئيسية'!B20 | C113: ورشة عمل تفاعلية | D113: أوراق عمل | E113: 45 دقيقة
A114: الأسبوع 7 | B114: ='الواجهة الرئيسية'!D20 | C114: ورشة عمل تفاعلية | D114: أوراق عمل | E114: 45 دقيقة
A115: الأسبوع 8 | B115: ='الواجهة الرئيسية'!F20 | C115: ورشة عمل تفاعلية | D115: أوراق عمل | E115: 45 دقيقة
A116: الأسبوع 9 | B116: ='الواجهة الرئيسية'!H20 | C116: ورشة عمل تفاعلية | D116: أوراق عمل | E116: 45 دقيقة
A117: الأسبوع 10 | B117: ='الواجهة الرئيسية'!J20 | C117: ورشة عمل تفاعلية | D117: أوراق عمل | E117: 45 دقيقة

Sheet الاختبار البعدي
A2: الاختبار التشخيصي البعدي – Post-Test
A3: إدخال درجات بعد التدريب | التحليل المقارن تلقائي
A4: م | B4: اسم الطالبة | C4: ="م1 " & CHAR(10) & 'الواجهة الرئيسية'!B8 | D4: ="م2 " & CHAR(10) & 'الواجهة الرئيسية'!D8 | E4: ="م3 " & CHAR(10) & 'الواجهة الرئيسية'!F8 | F4: ="م4 " & CHAR(10) & 'الواجهة الرئيسية'!H8 | G4: ="م5 " & CHAR(10) & 'الواجهة الرئيسية'!J8 | H4: ="م6 " & CHAR(10) & 'الواجهة الرئيسية'!B20 | I4: ="م7 " & CHAR(10) & 'الواجهة الرئيسية'!D20 | J4: ="م8 " & CHAR(10) & 'الواجهة الرئيسية'!F20 | K4: ="م9 " & CHAR(10) & 'الواجهة الرئيسية'!H20 | L4: ="م10 " & CHAR(10) & 'الواجهة الرئيسية'!J20 | M4: المجموع | N4: النسبة% | O4: المستوى
B5: الدرجة العظمى | C5: 10 | D5: 10 | E5: 10 | F5: 10 | G5: 10 | H5: 10 | I5: 10 | J5: 10 | K5: 10 | L5: 10 | M5: 100 | N5: 100%
A6: 1 | B6: ='قاعدة الأسماء'!B5 | C6: 9 | D6: 10 | E6: 10 | F6: 8 | G6: 10 | H6: 9 | I6: 10 | J6: 9 | K6: 10 | L6: 9 | M6: =IF(COUNT(C6:L6)=0,"",SUM(C6:L6)) | N6: =IF(M6="","",M6/100) | O6: =IF(M6="","",IF(M6<50,"ضعيف",IF(M6<75,"متوسط","ممتاز")))
A7: 2 | B7: ='قاعدة الأسماء'!B6 | C7: 10 | D7: 10 | E7: 9 | F7: 10 | G7: 10 | H7: 9 | I7: 9 | J7: 9 | K7: 8 | L7: 10 | M7: =IF(COUNT(C7:L7)=0,"",SUM(C7:L7)) | N7: =IF(M7="","",M7/100) | O7: =IF(M7="","",IF(M7<50,"ضعيف",IF(M7<75,"متوسط","ممتاز")))
A8: 3 | B8: ='قاعدة الأسماء'!B7 | C8: 10 | D8: 10 | E8: 10 | F8: 9 | G8: 10 | H8: 9 | I8: 10 | J8: 9 | K8: 10 | L8: 10 | M8: =IF(COUNT(C8:L8)=0,"",SUM(C8:L8)) | N8: =IF(M8="","",M8/100) | O8: =IF(M8="","",IF(M8<50,"ضعيف",IF(M8<75,"متوسط","ممتاز")))
A9: 4 | B9: ='قاعدة الأسماء'!B8 | C9: 10 | D9: 10 | E9: 9 | F9: 9 | G9: 10 | H9: 10 | I9: 10 | J9: 9 | K9: 10 | L9: 9 | M9: =IF(COUNT(C9:L9)=0,"",SUM(C9:L9)) | N9: =IF(M9="","",M9/100) | O9: =IF(M9="","",IF(M9<50,"ضعيف",IF(M9<75,"متوسط","ممتاز")))
A10: 5 | B10: ='قاعدة الأسماء'!B9 | C10: 10 | D10: 10 | E10: 10 | F10: 9 | G10: 10 | H10: 10 | I10: 9 | J10: 10 | K10: 9 | L10: 9 | M10: =IF(COUNT(C10:L10)=0,"",SUM(C10:L10)) | N10: =IF(M10="","",M10/100) | O10: =IF(M10="","",IF(M10<50,"ضعيف",IF(M10<75,"متوسط","ممتاز")))
A11: 6 | B11: ='قاعدة الأسماء'!B10 | C11: 10 | D11: 10 | E11: 8 | F11: 9 | G11: 9 | H11: 9 | I11: 10 | J11: 10 | K11: 9 | L11: 10 | M11: =IF(COUNT(C11:L11)=0,"",SUM(C11:L11)) | N11: =IF(M11="","",M11/100) | O11: =IF(M11="","",IF(M11<50,"ضعيف",IF(M11<75,"متوسط","ممتاز")))
A12: 7 | B12: ='قاعدة الأسماء'!B11 | C12: 9 | D12: 9 | E12: 9 | F12: 8 | G12: 9 | H12: 8 | I12: 9 | J12: 10 | K12: 8 | L12: 10 | M12: =IF(COUNT(C12:L12)=0,"",SUM(C12:L12)) | N12: =IF(M12="","",M12/100) | O12: =IF(M12="","",IF(M12<50,"ضعيف",IF(M12<75,"متوسط","ممتاز")))
A13: 8 | B13: ='قاعدة الأسماء'!B12 | C13: 10 | D13: 9 | E13: 8 | F13: 8 | G13: 10 | H13: 10 | I13: 10 | J13: 9 | K13: 10 | L13: 9 | M13: =IF(COUNT(C13:L13)=0,"",SUM(C13:L13)) | N13: =IF(M13="","",M13/100) | O13: =IF(M13="","",IF(M13<50,"ضعيف",IF(M13<75,"متوسط","ممتاز")))
A14: 9 | B14: ='قاعدة الأسماء'!B13 | C14: 10 | D14: 9 | E14: 9 | F14: 9 | G14: 10 | H14: 10 | I14: 10 | J14: 8 | K14: 10 | L14: 10 | M14: =IF(COUNT(C14:L14)=0,"",SUM(C14:L14)) | N14: =IF(M14="","",M14/100) | O14: =IF(M14="","",IF(M14<50,"ضعيف",IF(M14<75,"متوسط","ممتاز")))
A15: 10 | B15: ='قاعدة الأسماء'!B14 | C15: 10 | D15: 8 | E15: 8 | F15: 9 | G15: 9 | H15: 9 | I15: 10 | J15: 8 | K15: 9 | L15: 10 | M15: =IF(COUNT(C15:L15)=0,"",SUM(C15:L15)) | N15: =IF(M15="","",M15/100) | O15: =IF(M15="","",IF(M15<50,"ضعيف",IF(M15<75,"متوسط","ممتاز")))
A16: 11 | B16: ='قاعدة الأسماء'!B15 | C16: 10 | D16: 10 | E16: 9 | F16: 8 | G16: 10 | H16: 10 | I16: 10 | J16: 9 | K16: 10 | L16: 10 | M16: =IF(COUNT(C16:L16)=0,"",SUM(C16:L16)) | N16: =IF(M16="","",M16/100) | O16: =IF(M16="","",IF(M16<50,"ضعيف",IF(M16<75,"متوسط","ممتاز")))
A17: 12 | B17: ='قاعدة الأسماء'!B16 | C17: 10 | D17: 10 | E17: 10 | F17: 10 | G17: 10 | H17: 10 | I17: 9 | J17: 10 | K17: 10 | L17: 10 | M17: =IF(COUNT(C17:L17)=0,"",SUM(C17:L17)) | N17: =IF(M17="","",M17/100) | O17: =IF(M17="","",IF(M17<50,"ضعيف",IF(M17<75,"متوسط","ممتاز")))
... A104: 99 | B104: ='قاعدة الأسماء'!B103 | C104: 5 | D104: 5 | E104: 3 | F104: 4 | G104: 4 | H104: 3 | I104: 5 | J104: 4 | K104: 4 | L104: 4 | M104: =IF(COUNT(C104:L104)=0,"",SUM(C104:L104)) | N104: =IF(M104="","",M104/100) | O104: =IF(M104="","",IF(M104<50,"ضعيف",IF(M104<75,"متوسط","ممتاز")))
A107: تحليل النتائج الفوري والرسوم البيانية – Diagnostic Analytics & Charts
B109: المؤشرات العامة
B110: متوسط الدرجات | D110: =IFERROR(AVERAGE(M6:M104),0)
B111: نسبة النجاح | D111: =IFERROR(COUNTIF(O6:O104,"<>ضعيف")/99,0)
B112: أعلى درجة | D112: =IFERROR(MAX(M6:M104),0)
B113: أدنى درجة | D113: =IFERROR(MIN(M6:M104),0)
B115: توزيع مستويات الطالبات
B116: المستوى | C116: العدد | D116: النسبة%
B117: ممتاز | C117: =COUNTIF(O6:O104,"ممتاز") | D117: =C117/99
B118: متوسط | C118: =COUNTIF(O6:O104,"متوسط") | D118: =C118/99
B119: ضعيف | C119: =COUNTIF(O6:O104,"ضعيف") | D119: =C119/99
A121: مقارنة وتحليل متوسط درجات مهارات نافس العشر
B123: المهارة | C123: المتوسط | D123: التقييم
B124: ='الواجهة الرئيسية'!B8 | C124: =IFERROR(AVERAGE(C6:C104),0) | D124: =IF(C124>=7.5,"نقطة قوة",IF(C124>=5.0,"مستوى متوسط","تحتاج دعم"))
B125: ='الواجهة الرئيسية'!D8 | C125: =IFERROR(AVERAGE(D6:D104),0) | D125: =IF(C125>=7.5,"نقطة قوة",IF(C125>=5.0,"مستوى متوسط","تحتاج دعم"))
B126: ='الواجهة الرئيسية'!F8 | C126: =IFERROR(AVERAGE(E6:E104),0) | D126: =IF(C126>=7.5,"نقطة قوة",IF(C126>=5.0,"مستوى متوسط","تحتاج دعم"))
B127: ='الواجهة الرئيسية'!H8 | C127: =IFERROR(AVERAGE(F6:F104),0) | D127: =IF(C127>=7.5,"نقطة قوة",IF(C127>=5.0,"مستوى متوسط","تحتاج دعم"))
B128: ='الواجهة الرئيسية'!J8 | C128: =IFERROR(AVERAGE(G6:G104),0) | D128: =IF(C128>=7.5,"نقطة قوة",IF(C128>=5.0,"مستوى متوسط","تحتاج دعم"))
B129: ='الواجهة الرئيسية'!B20 | C129: =IFERROR(AVERAGE(H6:H104),0) | D129: =IF(C129>=7.5,"نقطة قوة",IF(C129>=5.0,"مستوى متوسط","تحتاج دعم"))
B130: ='الواجهة الرئيسية'!D20 | C130: =IFERROR(AVERAGE(I6:I104),0) | D130: =IF(C130>=7.5,"نقطة قوة",IF(C130>=5.0,"مستوى متوسط","تحتاج دعم"))
B131: ='الواجهة الرئيسية'!F20 | C131: =IFERROR(AVERAGE(J6:J104),0) | D131: =IF(C131>=7.5,"نقطة قوة",IF(C131>=5.0,"مستوى متوسط","تحتاج دعم"))
B132: ='الواجهة الرئيسية'!H20 | C132: =IFERROR(AVERAGE(K6:K104),0) | D132: =IF(C132>=7.5,"نقطة قوة",IF(C132>=5.0,"مستوى متوسط","تحتاج دعم"))
B133: ='الواجهة الرئيسية'!J20 | C133: =IFERROR(AVERAGE(L6:L104),0) | D133: =IF(C133>=7.5,"نقطة قوة",IF(C133>=5.0,"مستوى متوسط","تحتاج دعم"))

Sheet خطط بعدية
A2: الخطط العلاجية والإثرائية – البعدي
A3: تُنشأ الخطط تلقائياً بناءً على مستوى الطالبة
A4: م | B4: اسم الطالبة | C4: المستوى | D4: نوع الخطة | E4: المهارات المستهدفة | F4: الأنشطة | G4: ملاحظات | H4: تاريخ التنفيذ
A5: 1 | B5: ='قاعدة الأسماء'!B5 | C5: ='الاختبار البعدي'!O6 | D5: =IF(C5="ضعيف","خطة علاجية",IF(C5="متوسط","خطة تطويرية","خطة إثرائية")) | E5: =IF(C5="ضعيف","تركيز على: " & 'الواجهة الرئيسية'!B8 & " و " & 'الواجهة الرئيسية'!F8,IF(C5="متوسط","تطوير: " & 'الواجهة الرئيسية'!D8 & " و " & 'الواجهة الرئيسية'!H8,"إثراء: " & 'الواجهة الرئيسية'!H20 & " و " & 'الواجهة الرئيسية'!J20)) | F5: =IF(C5="ضعيف","تدريبات مكثفة – نماذج سابقة",IF(C5="متوسط","أنشطة تفاعلية – أوراق عمل","مشاريع بحثية – مسابقات نافس"))
A6: 2 | B6: ='قاعدة الأسماء'!B6 | C6: ='الاختبار البعدي'!O7 | D6: =IF(C6="ضعيف","خطة علاجية",IF(C6="متوسط","خطة تطويرية","خطة إثرائية")) | E6: =IF(C6="ضعيف","تركيز على: " & 'الواجهة الرئيسية'!B8 & " و " & 'الواجهة الرئيسية'!F8,IF(C6="متوسط","تطوير: " & 'الواجهة الرئيسية'!D8 & " و " & 'الواجهة الرئيسية'!H8,"إثراء: " & 'الواجهة الرئيسية'!H20 & " و " & 'الواجهة الرئيسية'!J20)) | F6: =IF(C6="ضعيف","تدريبات مكثفة – نماذج سابقة",IF(C6="متوسط","أنشطة تفاعلية – أوراق عمل","مشاريع بحثية – مسابقات نافس"))
A7: 3 | B7: ='قاعدة الأسماء'!B7 | C7: ='الاختبار البعدي'!O8 | D7: =IF(C7="ضعيف","خطة علاجية",IF(C7="متوسط","خطة تطويرية","خطة إثرائية")) | E7: =IF(C7="ضعيف","تركيز على: " & 'الواجهة الرئيسية'!B8 & " و " & 'الواجهة الرئيسية'!F8,IF(C7="متوسط","تطوير: " & 'الواجهة الرئيسية'!D8 & " و " & 'الواجهة الرئيسية'!H8,"إثراء: " & 'الواجهة الرئيسية'!H20 & " و " & 'الواجهة الرئيسية'!J20)) | F7: =IF(C7="ضعيف","تدريبات مكثفة – نماذج سابقة",IF(C7="متوسط","أنشطة تفاعلية – أوراق عمل","مشاريع بحثية – مسابقات نافس"))
A8: 4 | B8: ='قاعدة الأسماء'!B8 | C8: ='الاختبار البعدي'!O9 | D8: =IF(C8="ضعيف","خطة علاجية",IF(C8="متوسط","خطة تطويرية","خطة إثرائية")) | E8: =IF(C8="ضعيف","تركيز على: " & 'الواجهة الرئيسية'!B8 & " و " & 'الواجهة الرئيسية'!F8,IF(C8="متوسط","تطوير: " & 'الواجهة الرئيسية'!D8 & " و " & 'الواجهة الرئيسية'!H8,"إثراء: " & 'الواجهة الرئيسية'!H20 & " و " & 'الواجهة الرئيسية'!J20)) | F8: =IF(C8="ضعيف","تدريبات مكثفة – نماذج سابقة",IF(C8="متوسط","أنشطة تفاعلية – أوراق عمل","مشاريع بحثية – مسابقات نافس"))
A9: 5 | B9: ='قاعدة الأسماء'!B9 | C9: ='الاختبار البعدي'!O10 | D9: =IF(C9="ضعيف","خطة علاجية",IF(C9="متوسط","خطة تطويرية","خطة إثرائية")) | E9: =IF(C9="ضعيف","تركيز على: " & 'الواجهة الرئيسية'!B8 & " و " & 'الواجهة الرئيسية'!F8,IF(C9="متوسط","تطوير: " & 'الواجهة الرئيسية'!D8 & " و " & 'الواجهة الرئيسية'!H8,"إثراء: " & 'الواجهة الرئيسية'!H20 & " و " & 'الواجهة الرئيسية'!J20)) | F9: =IF(C9="ضعيف","تدريبات مكثفة – نماذج سابقة",IF(C9="متوسط","أنشطة تفاعلية – أوراق عمل","مشاريع بحثية – مسابقات نافس"))
A10: 6 | B10: ='قاعدة الأسماء'!B10 | C10: ='الاختبار البعدي'!O11 | D10: =IF(C10="ضعيف","خطة علاجية",IF(C10="متوسط","خطة تطويرية","خطة إثرائية")) | E10: =IF(C10="ضعيف","تركيز على: " & 'الواجهة الرئيسية'!B8 & " و " & 'الواجهة الرئيسية'!F8,IF(C10="متوسط","تطوير: " & 'الواجهة الرئيسية'!D8 & " و " & 'الواجهة الرئيسية'!H8,"إثراء: " & 'الواجهة الرئيسية'!H20 & " و " & 'الواجهة الرئيسية'!J20)) | F10: =IF(C10="ضعيف","تدريبات مكثفة – نماذج سابقة",IF(C10="متوسط","أنشطة تفاعلية – أوراق عمل","مشاريع بحثية – مسابقات نافس"))
A11: 7 | B11: ='قاعدة الأسماء'!B11 | C11: ='الاختبار البعدي'!O12 | D11: =IF(C11="ضعيف","خطة علاجية",IF(C11="متوسط","خطة تطويرية","خطة إثرائية")) | E11: =IF(C11="ضعيف","تركيز على: " & 'الواجهة الرئيسية'!B8 & " و " & 'الواجهة الرئيسية'!F8,IF(C11="متوسط","تطوير: " & 'الواجهة الرئيسية'!D8 & " و " & 'الواجهة الرئيسية'!H8,"إثراء: " & 'الواجهة الرئيسية'!H20 & " و " & 'الواجهة الرئيسية'!J20)) | F11: =IF(C11="ضعيف","تدريبات مكثفة – نماذج سابقة",IF(C11="متوسط","أنشطة تفاعلية – أوراق عمل","مشاريع بحثية – مسابقات نافس"))
A12: 8 | B12: ='قاعدة الأسماء'!B12 | C12: ='الاختبار البعدي'!O13 | D12: =IF(C12="ضعيف","خطة علاجية",IF(C12="متوسط","خطة تطويرية","خطة إثرائية")) | E12: =IF(C12="ضعيف","تركيز على: " & 'الواجهة الرئيسية'!B8 & " و " & 'الواجهة الرئيسية'!F8,IF(C12="متوسط","تطوير: " & 'الواجهة الرئيسية'!D8 & " و " & 'الواجهة الرئيسية'!H8,"إثراء: " & 'الواجهة الرئيسية'!H20 & " و " & 'الواجهة الرئيسية'!J20)) | F12: =IF(C12="ضعيف","تدريبات مكثفة – نماذج سابقة",IF(C12="متوسط","أنشطة تفاعلية – أوراق عمل","مشاريع بحثية – مسابقات نافس"))
A13: 9 | B13: ='قاعدة الأسماء'!B13 | C13: ='الاختبار البعدي'!O14 | D13: =IF(C13="ضعيف","خطة علاجية",IF(C13="متوسط","خطة تطويرية","خطة إثرائية")) | E13: =IF(C13="ضعيف","تركيز على: " & 'الواجهة الرئيسية'!B8 & " و " & 'الواجهة الرئيسية'!F8,IF(C13="متوسط","تطوير: " & 'الواجهة الرئيسية'!D8 & " و " & 'الواجهة الرئيسية'!H8,"إثراء: " & 'الواجهة الرئيسية'!H20 & " و " & 'الواجهة الرئيسية'!J20)) | F13: =IF(C13="ضعيف","تدريبات مكثفة – نماذج سابقة",IF(C13="متوسط","أنشطة تفاعلية – أوراق عمل","مشاريع بحثية – مسابقات نافس"))
A14: 10 | B14: ='قاعدة الأسماء'!B14 | C14: ='الاختبار البعدي'!O15 | D14: =IF(C14="ضعيف","خطة علاجية",IF(C14="متوسط","خطة تطويرية","خطة إثرائية")) | E14: =IF(C14="ضعيف","تركيز على: " & 'الواجهة الرئيسية'!B8 & " و " & 'الواجهة الرئيسية'!F8,IF(C14="متوسط","تطوير: " & 'الواجهة الرئيسية'!D8 & " و " & 'الواجهة الرئيسية'!H8,"إثراء: " & 'الواجهة الرئيسية'!H20 & " و " & 'الواجهة الرئيسية'!J20)) | F14: =IF(C14="ضعيف","تدريبات مكثفة – نماذج سابقة",IF(C14="متوسط","أنشطة تفاعلية – أوراق عمل","مشاريع بحثية – مسابقات نافس"))
A15: 11 | B15: ='قاعدة الأسماء'!B15 | C15: ='الاختبار البعدي'!O16 | D15: =IF(C15="ضعيف","خطة علاجية",IF(C15="متوسط","خطة تطويرية","خطة إثرائية")) | E15: =IF(C15="ضعيف","تركيز على: " & 'الواجهة الرئيسية'!B8 & " و " & 'الواجهة الرئيسية'!F8,IF(C15="متوسط","تطوير: " & 'الواجهة الرئيسية'!D8 & " و " & 'الواجهة الرئيسية'!H8,"إثراء: " & 'الواجهة الرئيسية'!H20 & " و " & 'الواجهة الرئيسية'!J20)) | F15: =IF(C15="ضعيف","تدريبات مكثفة – نماذج سابقة",IF(C15="متوسط","أنشطة تفاعلية – أوراق عمل","مشاريع بحثية – مسابقات نافس"))
A16: 12 | B16: ='قاعدة الأسماء'!B16 | C16: ='الاختبار البعدي'!O17 | D16: =IF(C16="ضعيف","خطة علاجية",IF(C16="متوسط","خطة تطويرية","خطة إثرائية")) | E16: =IF(C16="ضعيف","تركيز على: " & 'الواجهة الرئيسية'!B8 & " و " & 'الواجهة الرئيسية'!F8,IF(C16="متوسط","تطوير: " & 'الواجهة الرئيسية'!D8 & " و " & 'الواجهة الرئيسية'!H8,"إثراء: " & 'الواجهة الرئيسية'!H20 & " و " & 'الواجهة الرئيسية'!J20)) | F16: =IF(C16="ضعيف","تدريبات مكثفة – نماذج سابقة",IF(C16="متوسط","أنشطة تفاعلية – أوراق عمل","مشاريع بحثية – مسابقات نافس"))
A17: 13 | B17: ='قاعدة الأسماء'!B17 | C17: ='الاختبار البعدي'!O18 | D17: =IF(C17="ضعيف","خطة علاجية",IF(C17="متوسط","خطة تطويرية","خطة إثرائية")) | E17: =IF(C17="ضعيف","تركيز على: " & 'الواجهة الرئيسية'!B8 & " و " & 'الواجهة الرئيسية'!F8,IF(C17="متوسط","تطوير: " & 'الواجهة الرئيسية'!D8 & " و " & 'الواجهة الرئيسية'!H8,"إثراء: " & 'الواجهة الرئيسية'!H20 & " و " & 'الواجهة الرئيسية'!J20)) | F17: =IF(C17="ضعيف","تدريبات مكثفة – نماذج سابقة",IF(C17="متوسط","أنشطة تفاعلية – أوراق عمل","مشاريع بحثية – مسابقات نافس"))
A18: 14 | B18: ='قاعدة الأسماء'!B18 | C18: ='الاختبار البعدي'!O19 | D18: =IF(C18="ضعيف","خطة علاجية",IF(C18="متوسط","خطة تطويرية","خطة إثرائية")) | E18: =IF(C18="ضعيف","تركيز على: " & 'الواجهة الرئيسية'!B8 & " و " & 'الواجهة الرئيسية'!F8,IF(C18="متوسط","تطوير: " & 'الواجهة الرئيسية'!D8 & " و " & 'الواجهة الرئيسية'!H8,"إثراء: " & 'الواجهة الرئيسية'!H20 & " و " & 'الواجهة الرئيسية'!J20)) | F18: =IF(C18="ضعيف","تدريبات مكثفة – نماذج سابقة",IF(C18="متوسط","أنشطة تفاعلية – أوراق عمل","مشاريع بحثية – مسابقات نافس"))
A19: 15 | B19: ='قاعدة الأسماء'!B19 | C19: ='الاختبار البعدي'!O20 | D19: =IF(C19="ضعيف","خطة علاجية",IF(C19="متوسط","خطة تطويرية","خطة إثرائية")) | E19: =IF(C19="ضعيف","تركيز على: " & 'الواجهة الرئيسية'!B8 & " و " & 'الواجهة الرئيسية'!F8,IF(C19="متوسط","تطوير: " & 'الواجهة الرئيسية'!D8 & " و " & 'الواجهة الرئيسية'!H8,"إثراء: " & 'الواجهة الرئيسية'!H20 & " و " & 'الواجهة الرئيسية'!J20)) | F19: =IF(C19="ضعيف","تدريبات مكثفة – نماذج سابقة",IF(C19="متوسط","أنشطة تفاعلية – أوراق عمل","مشاريع بحثية – مسابقات نافس"))
A20: 16 | B20: ='قاعدة الأسماء'!B20 | C20: ='الاختبار البعدي'!O21 | D20: =IF(C20="ضعيف","خطة علاجية",IF(C20="متوسط","خطة تطويرية","خطة إثرائية")) | E20: =IF(C20="ضعيف","تركيز على: " & 'الواجهة الرئيسية'!B8 & " و " & 'الواجهة الرئيسية'!F8,IF(C20="متوسط","تطوير: " & 'الواجهة الرئيسية'!D8 & " و " & 'الواجهة الرئيسية'!H8,"إثراء: " & 'الواجهة الرئيسية'!H20 & " و " & 'الواجهة الرئيسية'!J20)) | F20: =IF(C20="ضعيف","تدريبات مكثفة – نماذج سابقة",IF(C20="متوسط","أنشطة تفاعلية – أوراق عمل","مشاريع بحثية – مسابقات نافس"))
A21: 17 | B21: ='قاعدة الأسماء'!B21 | C21: ='الاختبار البعدي'!O22 | D21: =IF(C21="ضعيف","خطة علاجية",IF(C21="متوسط","خطة تطويرية","خطة إثرائية")) | E21: =IF(C21="ضعيف","تركيز على: " & 'الواجهة الرئيسية'!B8 & " و " & 'الواجهة الرئيسية'!F8,IF(C21="متوسط","تطوير: " & 'الواجهة الرئيسية'!D8 & " و " & 'الواجهة الرئيسية'!H8,"إثراء: " & 'الواجهة الرئيسية'!H20 & " و " & 'الواجهة الرئيسية'!J20)) | F21: =IF(C21="ضعيف","تدريبات مكثفة – نماذج سابقة",IF(C21="متوسط","أنشطة تفاعلية – أوراق عمل","مشاريع بحثية – مسابقات نافس"))
A22: 18 | B22: ='قاعدة الأسماء'!B22 | C22: ='الاختبار البعدي'!O23 | D22: =IF(C22="ضعيف","خطة علاجية",IF(C22="متوسط","خطة تطويرية","خطة إثرائية")) | E22: =IF(C22="ضعيف","تركيز على: " & 'الواجهة الرئيسية'!B8 & " و " & 'الواجهة الرئيسية'!F8,IF(C22="متوسط","تطوير: " & 'الواجهة الرئيسية'!D8 & " و " & 'الواجهة الرئيسية'!H8,"إثراء: " & 'الواجهة الرئيسية'!H20 & " و " & 'الواجهة الرئيسية'!J20)) | F22: =IF(C22="ضعيف","تدريبات مكثفة – نماذج سابقة",IF(C22="متوسط","أنشطة تفاعلية – أوراق عمل","مشاريع بحثية – مسابقات نافس"))
A23: 19 | B23: ='قاعدة الأسماء'!B23 | C23: ='الاختبار البعدي'!O24 | D23: =IF(C23="ضعيف","خطة علاجية",IF(C23="متوسط","خطة تطويرية","خطة إثرائية")) | E23: =IF(C23="ضعيف","تركيز على: " & 'الواجهة الرئيسية'!B8 & " و " & 'الواجهة الرئيسية'!F8,IF(C23="متوسط","تطوير: " & 'الواجهة الرئيسية'!D8 & " و " & 'الواجهة الرئيسية'!H8,"إثراء: " & 'الواجهة الرئيسية'!H20 & " و " & 'الواجهة الرئيسية'!J20)) | F23: =IF(C23="ضعيف","تدريبات مكثفة – نماذج سابقة",IF(C23="متوسط","أنشطة تفاعلية – أوراق عمل","مشاريع بحثية – مسابقات نافس"))
A24: 20 | B24: ='قاعدة الأسماء'!B24 | C24: ='الاختبار البعدي'!O25 | D24: =IF(C24="ضعيف","خطة علاجية",IF(C24="متوسط","خطة تطويرية","خطة إثرائية")) | E24: =IF(C24="ضعيف","تركيز على: " & 'الواجهة الرئيسية'!B8 & " و " & 'الواجهة الرئيسية'!F8,IF(C24="متوسط","تطوير: " & 'الواجهة الرئيسية'!D8 & " و " & 'الواجهة الرئيسية'!H8,"إثراء: " & 'الواجهة الرئيسية'!H20 & " و " & 'الواجهة الرئيسية'!J20)) | F24: =IF(C24="ضعيف","تدريبات مكثفة – نماذج سابقة",IF(C24="متوسط","أنشطة تفاعلية – أوراق عمل","مشاريع بحثية – مسابقات نافس"))
A25: 21 | B25: ='قاعدة الأسماء'!B25 | C25: ='الاختبار البعدي'!O26 | D25: =IF(C25="ضعيف","خطة علاجية",IF(C25="متوسط","خطة تطويرية","خطة إثرائية")) | E25: =IF(C25="ضعيف","تركيز على: " & 'الواجهة الرئيسية'!B8 & " و " & 'الواجهة الرئيسية'!F8,IF(C25="متوسط","تطوير: " & 'الواجهة الرئيسية'!D8 & " و " & 'الواجهة الرئيسية'!H8,"إثراء: " & 'الواجهة الرئيسية'!H20 & " و " & 'الواجهة الرئيسية'!J20)) | F25: =IF(C25="ضعيف","تدريبات مكثفة – نماذج سابقة",IF(C25="متوسط","أنشطة تفاعلية – أوراق عمل","مشاريع بحثية – مسابقات نافس"))
A26: 22 | B26: ='قاعدة الأسماء'!B26 | C26: ='الاختبار البعدي'!O27 | D26: =IF(C26="ضعيف","خطة علاجية",IF(C26="متوسط","خطة تطويرية","خطة إثرائية")) | E26: =IF(C26="ضعيف","تركيز على: " & 'الواجهة الرئيسية'!B8 & " و " & 'الواجهة الرئيسية'!F8,IF(C26="متوسط","تطوير: " & 'الواجهة الرئيسية'!D8 & " و " & 'الواجهة الرئيسية'!H8,"إثراء: " & 'الواجهة الرئيسية'!H20 & " و " & 'الواجهة الرئيسية'!J20)) | F26: =IF(C26="ضعيف","تدريبات مكثفة – نماذج سابقة",IF(C26="متوسط","أنشطة تفاعلية – أوراق عمل","مشاريع بحثية – مسابقات نافس"))
A27: 23 | B27: ='قاعدة الأسماء'!B27 | C27: ='الاختبار البعدي'!O28 | D27: =IF(C27="ضعيف","خطة علاجية",IF(C27="متوسط","خطة تطويرية","خطة إثرائية")) | E27: =IF(C27="ضعيف","تركيز على: " & 'الواجهة الرئيسية'!B8 & " و " & 'الواجهة الرئيسية'!F8,IF(C27="متوسط","تطوير: " & 'الواجهة الرئيسية'!D8 & " و " & 'الواجهة الرئيسية'!H8,"إثراء: " & 'الواجهة الرئيسية'!H20 & " و " & 'الواجهة الرئيسية'!J20)) | F27: =IF(C27="ضعيف","تدريبات مكثفة – نماذج سابقة",IF(C27="متوسط","أنشطة تفاعلية – أوراق عمل","مشاريع بحثية – مسابقات نافس"))
A28: 24 | B28: ='قاعدة الأسماء'!B28 | C28: ='الاختبار البعدي'!O29 | D28: =IF(C28="ضعيف","خطة علاجية",IF(C28="متوسط","خطة تطويرية","خطة إثرائية")) | E28: =IF(C28="ضعيف","تركيز على: " & 'الواجهة الرئيسية'!B8 & " و " & 'الواجهة الرئيسية'!F8,IF(C28="متوسط","تطوير: " & 'الواجهة الرئيسية'!D8 & " و " & 'الواجهة الرئيسية'!H8,"إثراء: " & 'الواجهة الرئيسية'!H20 & " و " & 'الواجهة الرئيسية'!J20)) | F28: =IF(C28="ضعيف","تدريبات مكثفة – نماذج سابقة",IF(C28="متوسط","أنشطة تفاعلية – أوراق عمل","مشاريع بحثية – مسابقات نافس"))
A29: 25 | B29: ='قاعدة الأسماء'!B29 | C29: ='الاختبار البعدي'!O30 | D29: =IF(C29="ضعيف","خطة علاجية",IF(C29="متوسط","خطة تطويرية","خطة إثرائية")) | E29: =IF(C29="ضعيف","تركيز على: " & 'الواجهة الرئيسية'!B8 & " و " & 'الواجهة الرئيسية'!F8,IF(C29="متوسط","تطوير: " & 'الواجهة الرئيسية'!D8 & " و " & 'الواجهة الرئيسية'!H8,"إثراء: " & 'الواجهة الرئيسية'!H20 & " و " & 'الواجهة الرئيسية'!J20)) | F29: =IF(C29="ضعيف","تدريبات مكثفة – نماذج سابقة",IF(C29="متوسط","أنشطة تفاعلية – أوراق عمل","مشاريع بحثية – مسابقات نافس"))
A30: 26 | B30: ='قاعدة الأسماء'!B30 | C30: ='الاختبار البعدي'!O31 | D30: =IF(C30="ضعيف","خطة علاجية",IF(C30="متوسط","خطة تطويرية","خطة إثرائية")) | E30: =IF(C30="ضعيف","تركيز على: " & 'الواجهة الرئيسية'!B8 & " و " & 'الواجهة الرئيسية'!F8,IF(C30="متوسط","تطوير: " & 'الواجهة الرئيسية'!D8 & " و " & 'الواجهة الرئيسية'!H8,"إثراء: " & 'الواجهة الرئيسية'!H20 & " و " & 'الواجهة الرئيسية'!J20)) | F30: =IF(C30="ضعيف","تدريبات مكثفة – نماذج سابقة",IF(C30="متوسط","أنشطة تفاعلية – أوراق عمل","مشاريع بحثية – مسابقات نافس"))
A31: 27 | B31: ='قاعدة الأسماء'!B31 | C31: ='الاختبار البعدي'!O32 | D31: =IF(C31="ضعيف","خطة علاجية",IF(C31="متوسط","خطة تطويرية","خطة إثرائية")) | E31: =IF(C31="ضعيف","تركيز على: " & 'الواجهة الرئيسية'!B8 & " و " & 'الواجهة الرئيسية'!F8,IF(C31="متوسط","تطوير: " & 'الواجهة الرئيسية'!D8 & " و " & 'الواجهة الرئيسية'!H8,"إثراء: " & 'الواجهة الرئيسية'!H20 & " و " & 'الواجهة الرئيسية'!J20)) | F31: =IF(C31="ضعيف","تدريبات مكثفة – نماذج سابقة",IF(C31="متوسط","أنشطة تفاعلية – أوراق عمل","مشاريع بحثية – مسابقات نافس"))
A32: 28 | B32: ='قاعدة الأسماء'!B32 | C32: ='الاختبار البعدي'!O33 | D32: =IF(C32="ضعيف","خطة علاجية",IF(C32="متوسط","خطة تطويرية","خطة إثرائية")) | E32: =IF(C32="ضعيف","تركيز على: " & 'الواجهة الرئيسية'!B8 & " و " & 'الواجهة الرئيسية'!F8,IF(C32="متوسط","تطوير: " & 'الواجهة الرئيسية'!D8 & " و " & 'الواجهة الرئيسية'!H8,"إثراء: " & 'الواجهة الرئيسية'!H20 & " و " & 'الواجهة الرئيسية'!J20)) | F32: =IF(C32="ضعيف","تدريبات مكثفة – نماذج سابقة",IF(C32="متوسط","أنشطة تفاعلية – أوراق عمل","مشاريع بحثية – مسابقات نافس"))
A33: 29 | B33: ='قاعدة الأسماء'!B33 | C33: ='الاختبار البعدي'!O34 | D33: =IF(C33="ضعيف","خطة علاجية",IF(C33="متوسط","خطة تطويرية","خطة إثرائية")) | E33: =IF(C33="ضعيف","تركيز على: " & 'الواجهة الرئيسية'!B8 & " و " & 'الواجهة الرئيسية'!F8,IF(C33="متوسط","تطوير: " & 'الواجهة الرئيسية'!D8 & " و " & 'الواجهة الرئيسية'!H8,"إثراء: " & 'الواجهة الرئيسية'!H20 & " و " & 'الواجهة الرئيسية'!J20)) | F33: =IF(C33="ضعيف","تدريبات مكثفة – نماذج سابقة",IF(C33="متوسط","أنشطة تفاعلية – أوراق عمل","مشاريع بحثية – مسابقات نافس"))
A34: 30 | B34: ='قاعدة الأسماء'!B34 | C34: ='الاختبار البعدي'!O35 | D34: =IF(C34="ضعيف","خطة علاجية",IF(C34="متوسط","خطة تطويرية","خطة إثرائية")) | E34: =IF(C34="ضعيف","تركيز على: " & 'الواجهة الرئيسية'!B8 & " و " & 'الواجهة الرئيسية'!F8,IF(C34="متوسط","تطوير: " & 'الواجهة الرئيسية'!D8 & " و " & 'الواجهة الرئيسية'!H8,"إثراء: " & 'الواجهة الرئيسية'!H20 & " و " & 'الواجهة الرئيسية'!J20)) | F34: =IF(C34="ضعيف","تدريبات مكثفة – نماذج سابقة",IF(C34="متوسط","أنشطة تفاعلية – أوراق عمل","مشاريع بحثية – مسابقات نافس"))
A35: 31 | B35: ='قاعدة الأسماء'!B35 | C35: ='الاختبار البعدي'!O36 | D35: =IF(C35="ضعيف","خطة علاجية",IF(C35="متوسط","خطة تطويرية","خطة إثرائية")) | E35: =IF(C35="ضعيف","تركيز على: " & 'الواجهة الرئيسية'!B8 & " و " & 'الواجهة الرئيسية'!F8,IF(C35="متوسط","تطوير: " & 'الواجهة الرئيسية'!D8 & " و " & 'الواجهة الرئيسية'!H8,"إثراء: " & 'الواجهة الرئيسية'!H20 & " و " & 'الواجهة الرئيسية'!J20)) | F35: =IF(C35="ضعيف","تدريبات مكثفة – نماذج سابقة",IF(C35="متوسط","أنشطة تفاعلية – أوراق عمل","مشاريع بحثية – مسابقات نافس"))
A36: 32 | B36: ='قاعدة الأسماء'!B36 | C36: ='الاختبار البعدي'!O37 | D36: =IF(C36="ضعيف","خطة علاجية",IF(C36="متوسط","خطة تطويرية","خطة إثرائية")) | E36: =IF(C36="ضعيف","تركيز على: " & 'الواجهة الرئيسية'!B8 & " و " & 'الواجهة الرئيسية'!F8,IF(C36="متوسط","تطوير: " & 'الواجهة الرئيسية'!D8 & " و " & 'الواجهة الرئيسية'!H8,"إثراء: " & 'الواجهة الرئيسية'!H20 & " و " & 'الواجهة الرئيسية'!J20)) | F36: =IF(C36="ضعيف","تدريبات مكثفة – نماذج سابقة",IF(C36="متوسط","أنشطة تفاعلية – أوراق عمل","مشاريع بحثية – مسابقات نافس"))
A37: 33 | B37: ='قاعدة الأسماء'!B37 | C37: ='الاختبار البعدي'!O38 | D37: =IF(C37="ضعيف","خطة علاجية",IF(C37="متوسط","خطة تطويرية","خطة إثرائية")) | E37: =IF(C37="ضعيف","تركيز على: " & 'الواجهة الرئيسية'!B8 & " و " & 'الواجهة الرئيسية'!F8,IF(C37="متوسط","تطوير: " & 'الواجهة الرئيسية'!D8 & " و " & 'الواجهة الرئيسية'!H8,"إثراء: " & 'الواجهة الرئيسية'!H20 & " و " & 'الواجهة الرئيسية'!J20)) | F37: =IF(C37="ضعيف","تدريبات مكثفة – نماذج سابقة",IF(C37="متوسط","أنشطة تفاعلية – أوراق عمل","مشاريع بحثية – مسابقات نافس"))
A38: 34 | B38: ='قاعدة الأسماء'!B38 | C38: ='الاختبار البعدي'!O39 | D38: =IF(C38="ضعيف","خطة علاجية",IF(C38="متوسط","خطة تطويرية","خطة إثرائية")) | E38: =IF(C38="ضعيف","تركيز على: " & 'الواجهة الرئيسية'!B8 & " و " & 'الواجهة الرئيسية'!F8,IF(C38="متوسط","تطوير: " & 'الواجهة الرئيسية'!D8 & " و " & 'الواجهة الرئيسية'!H8,"إثراء: " & 'الواجهة الرئيسية'!H20 & " و " & 'الواجهة الرئيسية'!J20)) | F38: =IF(C38="ضعيف","تدريبات مكثفة – نماذج سابقة",IF(C38="متوسط","أنشطة تفاعلية – أوراق عمل","مشاريع بحثية – مسابقات نافس"))
A39: 35 | B39: ='قاعدة الأسماء'!B39 | C39: ='الاختبار البعدي'!O40 | D39: =IF(C39="ضعيف","خطة علاجية",IF(C39="متوسط","خطة تطويرية","خطة إثرائية")) | E39: =IF(C39="ضعيف","تركيز على: " & 'الواجهة الرئيسية'!B8 & " و " & 'الواجهة الرئيسية'!F8,IF(C39="متوسط","تطوير: " & 'الواجهة الرئيسية'!D8 & " و " & 'الواجهة الرئيسية'!H8,"إثراء: " & 'الواجهة الرئيسية'!H20 & " و " & 'الواجهة الرئيسية'!J20)) | F39: =IF(C39="ضعيف","تدريبات مكثفة – نماذج سابقة",IF(C39="متوسط","أنشطة تفاعلية – أوراق عمل","مشاريع بحثية – مسابقات نافس"))
A40: 36 | B40: ='قاعدة الأسماء'!B40 | C40: ='الاختبار البعدي'!O41 | D40: =IF(C40="ضعيف","خطة علاجية",IF(C40="متوسط","خطة تطويرية","خطة إثرائية")) | E40: =IF(C40="ضعيف","تركيز على: " & 'الواجهة الرئيسية'!B8 & " و " & 'الواجهة الرئيسية'!F8,IF(C40="متوسط","تطوير: " & 'الواجهة الرئيسية'!D8 & " و " & 'الواجهة الرئيسية'!H8,"إثراء: " & 'الواجهة الرئيسية'!H20 & " و " & 'الواجهة الرئيسية'!J20)) | F40: =IF(C40="ضعيف","تدريبات مكثفة – نماذج سابقة",IF(C40="متوسط","أنشطة تفاعلية – أوراق عمل","مشاريع بحثية – مسابقات نافس"))
A41: 37 | B41: ='قاعدة الأسماء'!B41 | C41: ='الاختبار البعدي'!O42 | D41: =IF(C41="ضعيف","خطة علاجية",IF(C41="متوسط","خطة تطويرية","خطة إثرائية")) | E41: =IF(C41="ضعيف","تركيز على: " & 'الواجهة الرئيسية'!B8 & " و " & 'الواجهة الرئيسية'!F8,IF(C41="متوسط","تطوير: " & 'الواجهة الرئيسية'!D8 & " و " & 'الواجهة الرئيسية'!H8,"إثراء: " & 'الواجهة الرئيسية'!H20 & " و " & 'الواجهة الرئيسية'!J20)) | F41: =IF(C41="ضعيف","تدريبات مكثفة – نماذج سابقة",IF(C41="متوسط","أنشطة تفاعلية – أوراق عمل","مشاريع بحثية – مسابقات نافس"))
...

Sheet مقارنة قبلي بعدي
A2: المقارنة الآلية بين الاختبار القبلي والبعدي
A3: يتم حساب الفرق ونسبة التحسن تلقائياً
A4: م | B4: اسم الطالبة | C4: درجة القبلي | D4: درجة البعدي | E4: الفرق (+/-) | F4: نسبة التحسن | G4: تقييم التحسن
A5: 1 | B5: ='قاعدة الأسماء'!B5 | C5: =IF('الاختبار القبلي'!M6="","—",'الاختبار القبلي'!M6) | D5: =IF('الاختبار البعدي'!M6="","—",'الاختبار البعدي'!M6) | E5: =IF(OR(C5="—",D5="—",C5="",D5=""),"",D5-C5) | F5: =IFERROR(IF(C5=0,IF(D5>0,1,0),(D5-C5)/C5),"") | G5: =IF(ISNUMBER(E5),IF(E5>10,"تحسن ممتاز",IF(E5>0,"تحسن إيجابي",IF(E5=0,"مستقر","تراجع"))),"—")
A6: 2 | B6: ='قاعدة الأسماء'!B6 | C6: =IF('الاختبار القبلي'!M7="","—",'الاختبار القبلي'!M7) | D6: =IF('الاختبار البعدي'!M7="","—",'الاختبار البعدي'!M7) | E6: =IF(OR(C6="—",D6="—",C6="",D6=""),"",D6-C6) | F6: =IFERROR(IF(C6=0,IF(D6>0,1,0),(D6-C6)/C6),"") | G6: =IF(ISNUMBER(E6),IF(E6>10,"تحسن ممتاز",IF(E6>0,"تحسن إيجابي",IF(E6=0,"مستقر","تراجع"))),"—")
A7: 3 | B7: ='قاعدة الأسماء'!B7 | C7: =IF('الاختبار القبلي'!M8="","—",'الاختبار القبلي'!M8) | D7: =IF('الاختبار البعدي'!M8="","—",'الاختبار البعدي'!M8) | E7: =IF(OR(C7="—",D7="—",C7="",D7=""),"",D7-C7) | F7: =IFERROR(IF(C7=0,IF(D7>0,1,0),(D7-C7)/C7),"") | G7: =IF(ISNUMBER(E7),IF(E7>10,"تحسن ممتاز",IF(E7>0,"تحسن إيجابي",IF(E7=0,"مستقر","تراجع"))),"—")
